Workbook
Name TIPOS_NOVEDAD: OFFSET(CONFIG!$A$4,0,0,MAX(1,COUNTA(CONFIG!$A$4:$A$63)),1)
Name CAUSAS_RAIZ: OFFSET(CONFIG!$G$4,0,0,MAX(1,COUNTA(CONFIG!$G$4:$G$63)),1)
Name ESTADOS_NOVEDAD: OFFSET(CONFIG!$K$4,0,0,MAX(1,COUNTA(CONFIG!$K$4:$K$63)),1)
Name PUNTOS_OCURRENCIA: OFFSET(CONFIG!$N$4,0,0,MAX(1,COUNTA(CONFIG!$N$4:$N$63)),1)
Name ORIGENES: OFFSET(CONFIG!$P$4,0,0,MAX(1,COUNTA(CONFIG!$P$4:$P$63)),1)
Name TRANSPORTADORAS: OFFSET(CONFIG!$R$4,0,0,MAX(1,COUNTA(CONFIG!$R$4:$R$63)),1)
Name RESPONSABLES: OFFSET(CONFIG!$T$4,0,0,MAX(1,COUNTA(CONFIG!$T$4:$T$63)),1)

Sheet INICIO
B2: MATRIZ DE NOVEDADES · LOGÍSTICA Y TRANSPORTE
C3: Un solo archivo para registrar todo lo que sale mal —en la carretera y dentro de la empresa—, saber a quién cobrárselo y medir si la operación está mejorando.
B4: CÓMO SE USA — TRES PASOS
B5: 1 | C5: ENVÍOS. Cada despacho es una fila. Escriba Nº de guía, Nº de pedido, fecha, cliente, ciudad, transportadora, conductor, placa, unidades, valor y la FECHA PROMESA DE ENTREGA. Cuando llegue, escriba la fecha de entrega real. Con eso el archivo calcula solo si llegó a tiempo y si llegó completo.
B6: 2 | C6: NOVEDADES. ¿Algo salió mal? Escriba la fecha, marque el ORIGEN y clasifique. Si fue en ruta, agregue el Nº de guía: el Nº de pedido, el cliente, la ciudad, la transportadora, el conductor y la placa se traen solos.
B7: 3 | C7: TABLERO. Ponga el periodo arriba y lea. Le dice su OTIF, qué transportadora rinde y cuál no, en qué punto de la operación se rompe y cuáles causas explican el 80% de sus problemas.
B8: LAS DOS CLASES DE NOVEDAD
C9: EN RUTA: pasó con un envío ya despachado (cliente ausente, avería, retraso, rechazo). Lleva Nº de guía y se le carga a la transportadora.
C10: INTERNA: pasó dentro de la empresa, casi siempre antes de despachar (error de alistamiento, descuadre de inventario, demora en el cargue, falla de un equipo de bodega, accidente laboral). NO lleva guía: deje esa casilla vacía y la validación dirá «Sin guía (interna)», que es lo correcto.
C11: Las internas nunca entran al scorecard de transportadoras ni a la tasa de novedades por envío, porque no son culpa del transportador ni corresponden a una entrega. Sí entran al Pareto de causas, a las 6M y al punto de ocurrencia — que es donde usted mira su propia casa.
B12: GUÍA Y PEDIDO
C13: La LLAVE es el Nº de guía o remisión: es el documento de transporte, uno por viaje, y es lo que amarra la novedad con el transportador. El Nº de pedido va al lado para dar trazabilidad de punta a punta: pedido → guía → cliente → novedad. No se usa como llave porque un mismo pedido puede salir en dos guías. En el buscador del tablero sirve cualquiera de los dos.
B14: LA REGLA DE COLORES
C15: AMARILLO = usted lo escribe. GRIS = se calcula solo, no lo toque. Encabezado dorado = columna de captura. Encabezado azul = columna calculada.
C16: Además, cada hoja tiene una banda oscura arriba que separa las zonas: lo que se digita, lo que se calcula y lo que es seguimiento.
B17: LOS NÚMEROS QUE IMPORTAN
C18: OTIF (On Time In Full): de los envíos ya entregados, cuántos llegaron a tiempo Y completos. Es el estándar de la industria; una operación sana anda por encima del 95%.
C19: TASA DE NOVEDADES: de cada 100 envíos, cuántos tuvieron algún problema en ruta. Cuenta envíos afectados, no novedades, para que no se infle cuando un envío genera tres.
C20: % INTERNAS: qué parte de sus novedades nace adentro. Si es alto, el problema no es el transportador.
C21: CUMPLIMIENTO DE SLA: de las novedades ya resueltas, cuántas se resolvieron dentro del plazo que usted mismo definió por tipo.
C22: PUNTAJE Y NOTA POR TRANSPORTADORA: A, B, C o D. Es la hoja que se lleva a la reunión de negociación.
B23: CÓMO CAMBIAR LAS REGLAS SIN TOCAR FÓRMULAS
C24: Todo vive en la hoja CONFIG: los tipos de novedad con su ámbito, su gravedad y su plazo en días hábiles; las causas raíz con su familia 6M y su área responsable; los estados y cuáles cierran el caso; los puntos de ocurrencia, las transportadoras y los responsables.
C25: Agregue filas hacia abajo y listo: las listas desplegables crecen solas y el tablero las recoge en el siguiente cálculo. Reemplace «Transportadora A, B, C» por los nombres reales antes de empezar.
B26: SOBRE LA CAUSA RAÍZ (LAS 6M)
C27: Cada causa está clasificada en una de las seis familias del diagrama de Ishikawa: Método, Material, Medición, Mano de obra, Máquina y Medio ambiente (más Externo y Por definir). Sirve para ver si sus problemas son de proceso, de gente, de equipos o de afuera — y esa respuesta cambia qué se hace al respecto.
B28: DETALLES PRÁCTICOS
C29: Las hojas están protegidas para no dañar las fórmulas, pero SIN contraseña: Revisar → Desproteger hoja y ya. Los plazos se cuentan en días hábiles (sin sábados ni domingos); si quiere descontar festivos, agregue una columna de fechas festivas en CONFIG y páselas como tercer argumento de DIA.LAB.
C30: Capacidad: 3.000 envíos y 1.500 novedades. Cuando se acerque al tope, guarde una copia con el nombre del periodo y borre solo las celdas amarillas.

Sheet TABLERO
B2: TABLERO DE NOVEDADES · logística y transporte
B3: Todo se filtra por el periodo de abajo. Novedades por su fecha de registro; envíos por su fecha de despacho.
B4: PERIODO | D4: Desde: | E4: 46023 | F4: Hasta: | G4: 46387 | H4: ◄ cambie estas dos fechas y todo el tablero se recalcula
B6: LAS ENTREGAS | D6: OTIF (a tiempo y completo) | F6: ENTREGAS A TIEMPO | H6: TASA DE NOVEDADES | J6: VALOR AFECTADO | L6: ENVÍOS DEL PERIODO
D7: =IFERROR(COUNTIFS(ENVIOS!$Q$4:$Q$3003,"OTIF",ENVIOS!$C$4:$C$3003,">="&$E$4,ENVIOS!$C$4:$C$3003,"<="&$G$4)/(COUNTIFS(ENVIOS!$Q$4:$Q$3003,"OTIF",ENVIOS!$C$4:$C$3003,">="&$E$4,ENVIOS!$C$4:$C$3003,"<="&$G$4)+COUNTIFS(ENVIOS!$Q$4:$Q$3003,"Falló",ENVIOS!$C$4:$C$3003,">="&$E$4,ENVIOS!$C$4:$C$3003,"<="&$G$4)),"—") | F7: =IFERROR(COUNTIFS(ENVIOS!$N$4:$N$3003,"Sí",ENVIOS!$C$4:$C$3003,">="&$E$4,ENVIOS!$C$4:$C$3003,"<="&$G$4)/(COUNTIFS(ENVIOS!$Q$4:$Q$3003,"OTIF",ENVIOS!$C$4:$C$3003,">="&$E$4,ENVIOS!$C$4:$C$3003,"<="&$G$4)+COUNTIFS(ENVIOS!$Q$4:$Q$3003,"Falló",ENVIOS!$C$4:$C$3003,">="&$E$4,ENVIOS!$C$4:$C$3003,"<="&$G$4)),"—") | H7: =IFERROR(COUNTIFS(ENVIOS!$O$4:$O$3003,">0",ENVIOS!$C$4:$C$3003,">="&$E$4,ENVIOS!$C$4:$C$3003,"<="&$G$4)/COUNTIFS(ENVIOS!$C$4:$C$3003,">="&$E$4,ENVIOS!$C$4:$C$3003,"<="&$G$4),"—") | J7: =SUMIFS(NOVEDADES!$U$4:$U$1503,NOVEDADES!$B$4:$B$1503,">="&$E$4,NOVEDADES!$B$4:$B$1503,"<="&$G$4) | L7: =COUNTIFS(ENVIOS!$C$4:$C$3003,">="&$E$4,ENVIOS!$C$4:$C$3003,"<="&$G$4)
B9: LA GESTIÓN | D9: NOVEDADES | F9: ABIERTAS | H9: VENCIDAS (SLA roto) | J9: DÍAS PROM. SOLUCIÓN | L9: CUMPLIMIENTO DE SLA
D10: =COUNTIFS(NOVEDADES!$B$4:$B$1503,">="&$E$4,NOVEDADES!$B$4:$B$1503,"<="&$G$4) | F10: =COUNTIFS(NOVEDADES!$AA$4:$AA$1503,"En plazo",NOVEDADES!$B$4:$B$1503,">="&$E$4,NOVEDADES!$B$4:$B$1503,"<="&$G$4)+COUNTIFS(NOVEDADES!$AA$4:$AA$1503,"Por vencer",NOVEDADES!$B$4:$B$1503,">="&$E$4,NOVEDADES!$B$4:$B$1503,"<="&$G$4)+COUNTIFS(NOVEDADES!$AA$4:$AA$1503,"Vencida",NOVEDADES!$B$4:$B$1503,">="&$E$4,NOVEDADES!$B$4:$B$1503,"<="&$G$4)+COUNTIFS(NOVEDADES!$AA$4:$AA$1503,"Sin clasificar",NOVEDADES!$B$4:$B$1503,">="&$E$4,NOVEDADES!$B$4:$B$1503,"<="&$G$4) | H10: =COUNTIFS(NOVEDADES!$AA$4:$AA$1503,"Vencida",NOVEDADES!$B$4:$B$1503,">="&$E$4,NOVEDADES!$B$4:$B$1503,"<="&$G$4) | J10: =IFERROR(ROUND(AVERAGEIFS(NOVEDADES!$Z$4:$Z$1503,NOVEDADES!$B$4:$B$1503,">="&$E$4,NOVEDADES!$B$4:$B$1503,"<="&$G$4),1),0) | L10: =IFERROR(COUNTIFS(NOVEDADES!$AA$4:$AA$1503,"Resuelta a tiempo",NOVEDADES!$B$4:$B$1503,">="&$E$4,NOVEDADES!$B$4:$B$1503,"<="&$G$4)/COUNTIFS(NOVEDADES!$AA$4:$AA$1503,"Resuelta*",NOVEDADES!$B$4:$B$1503,">="&$E$4,NOVEDADES!$B$4:$B$1503,"<="&$G$4),"—")
B12: DÓNDE NACEN | D12: EN RUTA (transporte) | F12: INTERNAS (la empresa) | H12: % INTERNAS | J12: VALOR DE LAS INTERNAS | L12: PUNTO INTERNO MÁS FRECUENTE
D13: =COUNTIFS(NOVEDADES!$C$4:$C$1503,"En ruta",NOVEDADES!$B$4:$B$1503,">="&$E$4,NOVEDADES!$B$4:$B$1503,"<="&$G$4) | F13: =COUNTIFS(NOVEDADES!$C$4:$C$1503,"Interna",NOVEDADES!$B$4:$B$1503,">="&$E$4,NOVEDADES!$B$4:$B$1503,"<="&$G$4) | H13: =IFERROR(COUNTIFS(NOVEDADES!$C$4:$C$1503,"Interna",NOVEDADES!$B$4:$B$1503,">="&$E$4,NOVEDADES!$B$4:$B$1503,"<="&$G$4)/COUNTIFS(NOVEDADES!$B$4:$B$1503,">="&$E$4,NOVEDADES!$B$4:$B$1503,"<="&$G$4),"—") | J13: =SUMIFS(NOVEDADES!$U$4:$U$1503,NOVEDADES!$C$4:$C$1503,"Interna",NOVEDADES!$B$4:$B$1503,">="&$E$4,NOVEDADES!$B$4:$B$1503,"<="&$G$4) | L13: =IF(MAX($D$87:$D$97)=0,"—",IFERROR(INDEX($B$87:$B$97,MATCH(MAX($D$87:$D$97),$D$87:$D$97,0)),"—"))
B15: 1 · SCORECARD DE TRANSPORTADORAS | O15: Las gráficas se recalculan con el periodo de arriba.
B16: Solo cuenta las novedades EN RUTA: las internas no son culpa del transportador. Nota A = 90 puntos o más · B = 80 a 89 · C = 70 a 79 · D = menos de 70. Puntaje = OTIF ×60 + (1 − tasa) ×25 + (1 − vencidas/novedades) ×15.
B17: Transportadora | D17: Envíos | E17: OTIF | F17: Novedades | G17: Tasa | H17: Abiertas | I17: Vencidas | J17: Días prom. | K17: Valor afectado | L17: Puntaje | M17: Nota
B18: =IF(CONFIG!$R4="","",CONFIG!$R4) | D18: =IF($B18="","",COUNTIFS(ENVIOS!$F$4:$F$3003,$B18,ENVIOS!$C$4:$C$3003,">="&$E$4,ENVIOS!$C$4:$C$3003,"<="&$G$4)) | E18: =IF($B18="","",IFERROR(COUNTIFS(ENVIOS!$F$4:$F$3003,$B18,ENVIOS!$Q$4:$Q$3003,"OTIF",ENVIOS!$C$4:$C$3003,">="&$E$4,ENVIOS!$C$4:$C$3003,"<="&$G$4)/(COUNTIFS(ENVIOS!$F$4:$F$3003,$B18,ENVIOS!$Q$4:$Q$3003,"OTIF",ENVIOS!$C$4:$C$3003,">="&$E$4,ENVIOS!$C$4:$C$3003,"<="&$G$4)+COUNTIFS(ENVIOS!$F$4:$F$3003,$B18,ENVIOS!$Q$4:$Q$3003,"Falló",ENVIOS!$C$4:$C$3003,">="&$E$4,ENVIOS!$C$4:$C$3003,"<="&$G$4)),"—")) | F18: =IF($B18="","",COUNTIFS(NOVEDADES!$I$4:$I$1503,$B18,NOVEDADES!$B$4:$B$1503,">="&$E$4,NOVEDADES!$B$4:$B$1503,"<="&$G$4)) | G18: =IF($B18="","",IFERROR(COUNTIFS(ENVIOS!$F$4:$F$3003,$B18,ENVIOS!$O$4:$O$3003,">0",ENVIOS!$C$4:$C$3003,">="&$E$4,ENVIOS!$C$4:$C$3003,"<="&$G$4)/$D18,"—")) | H18: =IF($B18="","",COUNTIFS(NOVEDADES!$AA$4:$AA$1503,"En plazo",NOVEDADES!$B$4:$B$1503,">="&$E$4,NOVEDADES!$B$4:$B$1503,"<="&$G$4,NOVEDADES!$I$4:$I$1503,$B18)+COUNTIFS(NOVEDADES!$AA$4:$AA$1503,"Por vencer",NOVEDADES!$B$4:$B$1503,">="&$E$4,NOVEDADES!$B$4:$B$1503,"<="&$G$4,NOVEDADES!$I$4:$I$1503,$B18)+COUNTIFS(NOVEDADES!$AA$4:$AA$1503,"Vencida",NOVEDADES!$B$4:$B$1503,">="&$E$4,NOVEDADES!$B$4:$B$1503,"<="&$G$4,NOVEDADES!$I$4:$I$1503,$B18)+COUNTIFS(NOVEDADES!$AA$4:$AA$1503,"Sin clasificar",NOVEDADES!$B$4:$B$1503,">="&$E$4,NOVEDADES!$B$4:$B$1503,"<="&$G$4,NOVEDADES!$I$4:$I$1503,$B18)) | I18: =IF($B18="","",COUNTIFS(NOVEDADES!$I$4:$I$1503,$B18,NOVEDADES!$AA$4:$AA$1503,"Vencida",NOVEDADES!$B$4:$B$1503,">="&$E$4,NOVEDADES!$B$4:$B$1503,"<="&$G$4)) | J18: =IF($B18="","",IFERROR(ROUND(AVERAGEIFS(NOVEDADES!$Z$4:$Z$1503,NOVEDADES!$I$4:$I$1503,$B18,NOVEDADES!$B$4:$B$1503,">="&$E$4,NOVEDADES!$B$4:$B$1503,"<="&$G$4),1),0)) | K18: =IF($B18="","",SUMIFS(NOVEDADES!$U$4:$U$1503,NOVEDADES!$I$4:$I$1503,$B18,NOVEDADES!$B$4:$B$1503,">="&$E$4,NOVEDADES!$B$4:$B$1503,"<="&$G$4)) | L18: =IF(OR($B18="",$D18=0,NOT(ISNUMBER($E18))),"—",ROUND($E18*60+(1-N($G18))*25+IF($F18=0,15,(1-$I18/$F18)*15),0)) | M18: =IF(NOT(ISNUMBER($L18)),"—",IF($L18>=90,"A",IF($L18>=80,"B",IF($L18>=70,"C","D"))))
B19: =IF(CONFIG!$R5="","",CONFIG!$R5) | D19: =IF($B19="","",COUNTIFS(ENVIOS!$F$4:$F$3003,$B19,ENVIOS!$C$4:$C$3003,">="&$E$4,ENVIOS!$C$4:$C$3003,"<="&$G$4)) | E19: =IF($B19="","",IFERROR(COUNTIFS(ENVIOS!$F$4:$F$3003,$B19,ENVIOS!$Q$4:$Q$3003,"OTIF",ENVIOS!$C$4:$C$3003,">="&$E$4,ENVIOS!$C$4:$C$3003,"<="&$G$4)/(COUNTIFS(ENVIOS!$F$4:$F$3003,$B19,ENVIOS!$Q$4:$Q$3003,"OTIF",ENVIOS!$C$4:$C$3003,">="&$E$4,ENVIOS!$C$4:$C$3003,"<="&$G$4)+COUNTIFS(ENVIOS!$F$4:$F$3003,$B19,ENVIOS!$Q$4:$Q$3003,"Falló",ENVIOS!$C$4:$C$3003,">="&$E$4,ENVIOS!$C$4:$C$3003,"<="&$G$4)),"—")) | F19: =IF($B19="","",COUNTIFS(NOVEDADES!$I$4:$I$1503,$B19,NOVEDADES!$B$4:$B$1503,">="&$E$4,NOVEDADES!$B$4:$B$1503,"<="&$G$4)) | G19: =IF($B19="","",IFERROR(COUNTIFS(ENVIOS!$F$4:$F$3003,$B19,ENVIOS!$O$4:$O$3003,">0",ENVIOS!$C$4:$C$3003,">="&$E$4,ENVIOS!$C$4:$C$3003,"<="&$G$4)/$D19,"—")) | H19: =IF($B19="","",COUNTIFS(NOVEDADES!$AA$4:$AA$1503,"En plazo",NOVEDADES!$B$4:$B$1503,">="&$E$4,NOVEDADES!$B$4:$B$1503,"<="&$G$4,NOVEDADES!$I$4:$I$1503,$B19)+COUNTIFS(NOVEDADES!$AA$4:$AA$1503,"Por vencer",NOVEDADES!$B$4:$B$1503,">="&$E$4,NOVEDADES!$B$4:$B$1503,"<="&$G$4,NOVEDADES!$I$4:$I$1503,$B19)+COUNTIFS(NOVEDADES!$AA$4:$AA$1503,"Vencida",NOVEDADES!$B$4:$B$1503,">="&$E$4,NOVEDADES!$B$4:$B$1503,"<="&$G$4,NOVEDADES!$I$4:$I$1503,$B19)+COUNTIFS(NOVEDADES!$AA$4:$AA$1503,"Sin clasificar",NOVEDADES!$B$4:$B$1503,">="&$E$4,NOVEDADES!$B$4:$B$1503,"<="&$G$4,NOVEDADES!$I$4:$I$1503,$B19)) | I19: =IF($B19="","",COUNTIFS(NOVEDADES!$I$4:$I$1503,$B19,NOVEDADES!$AA$4:$AA$1503,"Vencida",NOVEDADES!$B$4:$B$1503,">="&$E$4,NOVEDADES!$B$4:$B$1503,"<="&$G$4)) | J19: =IF($B19="","",IFERROR(ROUND(AVERAGEIFS(NOVEDADES!$Z$4:$Z$1503,NOVEDADES!$I$4:$I$1503,$B19,NOVEDADES!$B$4:$B$1503,">="&$E$4,NOVEDADES!$B$4:$B$1503,"<="&$G$4),1),0)) | K19: =IF($B19="","",SUMIFS(NOVEDADES!$U$4:$U$1503,NOVEDADES!$I$4:$I$1503,$B19,NOVEDADES!$B$4:$B$1503,">="&$E$4,NOVEDADES!$B$4:$B$1503,"<="&$G$4)) | L19: =IF(OR($B19="",$D19=0,NOT(ISNUMBER($E19))),"—",ROUND($E19*60+(1-N($G19))*25+IF($F19=0,15,(1-$I19/$F19)*15),0)) | M19: =IF(NOT(ISNUMBER($L19)),"—",IF($L19>=90,"A",IF($L19>=80,"B",IF($L19>=70,"C","D"))))
B20: =IF(CONFIG!$R6="","",CONFIG!$R6) | D20: =IF($B20="","",COUNTIFS(ENVIOS!$F$4:$F$3003,$B20,ENVIOS!$C$4:$C$3003,">="&$E$4,ENVIOS!$C$4:$C$3003,"<="&$G$4)) | E20: =IF($B20="","",IFERROR(COUNTIFS(ENVIOS!$F$4:$F$3003,$B20,ENVIOS!$Q$4:$Q$3003,"OTIF",ENVIOS!$C$4:$C$3003,">="&$E$4,ENVIOS!$C$4:$C$3003,"<="&$G$4)/(COUNTIFS(ENVIOS!$F$4:$F$3003,$B20,ENVIOS!$Q$4:$Q$3003,"OTIF",ENVIOS!$C$4:$C$3003,">="&$E$4,ENVIOS!$C$4:$C$3003,"<="&$G$4)+COUNTIFS(ENVIOS!$F$4:$F$3003,$B20,ENVIOS!$Q$4:$Q$3003,"Falló",ENVIOS!$C$4:$C$3003,">="&$E$4,ENVIOS!$C$4:$C$3003,"<="&$G$4)),"—")) | F20: =IF($B20="","",COUNTIFS(NOVEDADES!$I$4:$I$1503,$B20,NOVEDADES!$B$4:$B$1503,">="&$E$4,NOVEDADES!$B$4:$B$1503,"<="&$G$4)) | G20: =IF($B20="","",IFERROR(COUNTIFS(ENVIOS!$F$4:$F$3003,$B20,ENVIOS!$O$4:$O$3003,">0",ENVIOS!$C$4:$C$3003,">="&$E$4,ENVIOS!$C$4:$C$3003,"<="&$G$4)/$D20,"—")) | H20: =IF($B20="","",COUNTIFS(NOVEDADES!$AA$4:$AA$1503,"En plazo",NOVEDADES!$B$4:$B$1503,">="&$E$4,NOVEDADES!$B$4:$B$1503,"<="&$G$4,NOVEDADES!$I$4:$I$1503,$B20)+COUNTIFS(NOVEDADES!$AA$4:$AA$1503,"Por vencer",NOVEDADES!$B$4:$B$1503,">="&$E$4,NOVEDADES!$B$4:$B$1503,"<="&$G$4,NOVEDADES!$I$4:$I$1503,$B20)+COUNTIFS(NOVEDADES!$AA$4:$AA$1503,"Vencida",NOVEDADES!$B$4:$B$1503,">="&$E$4,NOVEDADES!$B$4:$B$1503,"<="&$G$4,NOVEDADES!$I$4:$I$1503,$B20)+COUNTIFS(NOVEDADES!$AA$4:$AA$1503,"Sin clasificar",NOVEDADES!$B$4:$B$1503,">="&$E$4,NOVEDADES!$B$4:$B$1503,"<="&$G$4,NOVEDADES!$I$4:$I$1503,$B20)) | I20: =IF($B20="","",COUNTIFS(NOVEDADES!$I$4:$I$1503,$B20,NOVEDADES!$AA$4:$AA$1503,"Vencida",NOVEDADES!$B$4:$B$1503,">="&$E$4,NOVEDADES!$B$4:$B$1503,"<="&$G$4)) | J20: =IF($B20="","",IFERROR(ROUND(AVERAGEIFS(NOVEDADES!$Z$4:$Z$1503,NOVEDADES!$I$4:$I$1503,$B20,NOVEDADES!$B$4:$B$1503,">="&$E$4,NOVEDADES!$B$4:$B$1503,"<="&$G$4),1),0)) | K20: =IF($B20="","",SUMIFS(NOVEDADES!$U$4:$U$1503,NOVEDADES!$I$4:$I$1503,$B20,NOVEDADES!$B$4:$B$1503,">="&$E$4,NOVEDADES!$B$4:$B$1503,"<="&$G$4)) | L20: =IF(OR($B20="",$D20=0,NOT(ISNUMBER($E20))),"—",ROUND($E20*60+(1-N($G20))*25+IF($F20=0,15,(1-$I20/$F20)*15),0)) | M20: =IF(NOT(ISNUMBER($L20)),"—",IF($L20>=90,"A",IF($L20>=80,"B",IF($L20>=70,"C","D"))))
B21: =IF(CONFIG!$R7="","",CONFIG!$R7) | D21: =IF($B21="","",COUNTIFS(ENVIOS!$F$4:$F$3003,$B21,ENVIOS!$C$4:$C$3003,">="&$E$4,ENVIOS!$C$4:$C$3003,"<="&$G$4)) | E21: =IF($B21="","",IFERROR(COUNTIFS(ENVIOS!$F$4:$F$3003,$B21,ENVIOS!$Q$4:$Q$3003,"OTIF",ENVIOS!$C$4:$C$3003,">="&$E$4,ENVIOS!$C$4:$C$3003,"<="&$G$4)/(COUNTIFS(ENVIOS!$F$4:$F$3003,$B21,ENVIOS!$Q$4:$Q$3003,"OTIF",ENVIOS!$C$4:$C$3003,">="&$E$4,ENVIOS!$C$4:$C$3003,"<="&$G$4)+COUNTIFS(ENVIOS!$F$4:$F$3003,$B21,ENVIOS!$Q$4:$Q$3003,"Falló",ENVIOS!$C$4:$C$3003,">="&$E$4,ENVIOS!$C$4:$C$3003,"<="&$G$4)),"—")) | F21: =IF($B21="","",COUNTIFS(NOVEDADES!$I$4:$I$1503,$B21,NOVEDADES!$B$4:$B$1503,">="&$E$4,NOVEDADES!$B$4:$B$1503,"<="&$G$4)) | G21: =IF($B21="","",IFERROR(COUNTIFS(ENVIOS!$F$4:$F$3003,$B21,ENVIOS!$O$4:$O$3003,">0",ENVIOS!$C$4:$C$3003,">="&$E$4,ENVIOS!$C$4:$C$3003,"<="&$G$4)/$D21,"—")) | H21: =IF($B21="","",COUNTIFS(NOVEDADES!$AA$4:$AA$1503,"En plazo",NOVEDADES!$B$4:$B$1503,">="&$E$4,NOVEDADES!$B$4:$B$1503,"<="&$G$4,NOVEDADES!$I$4:$I$1503,$B21)+COUNTIFS(NOVEDADES!$AA$4:$AA$1503,"Por vencer",NOVEDADES!$B$4:$B$1503,">="&$E$4,NOVEDADES!$B$4:$B$1503,"<="&$G$4,NOVEDADES!$I$4:$I$1503,$B21)+COUNTIFS(NOVEDADES!$AA$4:$AA$1503,"Vencida",NOVEDADES!$B$4:$B$1503,">="&$E$4,NOVEDADES!$B$4:$B$1503,"<="&$G$4,NOVEDADES!$I$4:$I$1503,$B21)+COUNTIFS(NOVEDADES!$AA$4:$AA$1503,"Sin clasificar",NOVEDADES!$B$4:$B$1503,">="&$E$4,NOVEDADES!$B$4:$B$1503,"<="&$G$4,NOVEDADES!$I$4:$I$1503,$B21)) | I21: =IF($B21="","",COUNTIFS(NOVEDADES!$I$4:$I$1503,$B21,NOVEDADES!$AA$4:$AA$1503,"Vencida",NOVEDADES!$B$4:$B$1503,">="&$E$4,NOVEDADES!$B$4:$B$1503,"<="&$G$4)) | J21: =IF($B21="","",IFERROR(ROUND(AVERAGEIFS(NOVEDADES!$Z$4:$Z$1503,NOVEDADES!$I$4:$I$1503,$B21,NOVEDADES!$B$4:$B$1503,">="&$E$4,NOVEDADES!$B$4:$B$1503,"<="&$G$4),1),0)) | K21: =IF($B21="","",SUMIFS(NOVEDADES!$U$4:$U$1503,NOVEDADES!$I$4:$I$1503,$B21,NOVEDADES!$B$4:$B$1503,">="&$E$4,NOVEDADES!$B$4:$B$1503,"<="&$G$4)) | L21: =IF(OR($B21="",$D21=0,NOT(ISNUMBER($E21))),"—",ROUND($E21*60+(1-N($G21))*25+IF($F21=0,15,(1-$I21/$F21)*15),0)) | M21: =IF(NOT(ISNUMBER($L21)),"—",IF($L21>=90,"A",IF($L21>=80,"B",IF($L21>=70,"C","D"))))
B22: =IF(CONFIG!$R8="","",CONFIG!$R8) | D22: =IF($B22="","",COUNTIFS(ENVIOS!$F$4:$F$3003,$B22,ENVIOS!$C$4:$C$3003,">="&$E$4,ENVIOS!$C$4:$C$3003,"<="&$G$4)) | E22: =IF($B22="","",IFERROR(COUNTIFS(ENVIOS!$F$4:$F$3003,$B22,ENVIOS!$Q$4:$Q$3003,"OTIF",ENVIOS!$C$4:$C$3003,">="&$E$4,ENVIOS!$C$4:$C$3003,"<="&$G$4)/(COUNTIFS(ENVIOS!$F$4:$F$3003,$B22,ENVIOS!$Q$4:$Q$3003,"OTIF",ENVIOS!$C$4:$C$3003,">="&$E$4,ENVIOS!$C$4:$C$3003,"<="&$G$4)+COUNTIFS(ENVIOS!$F$4:$F$3003,$B22,ENVIOS!$Q$4:$Q$3003,"Falló",ENVIOS!$C$4:$C$3003,">="&$E$4,ENVIOS!$C$4:$C$3003,"<="&$G$4)),"—")) | F22: =IF($B22="","",COUNTIFS(NOVEDADES!$I$4:$I$1503,$B22,NOVEDADES!$B$4:$B$1503,">="&$E$4,NOVEDADES!$B$4:$B$1503,"<="&$G$4)) | G22: =IF($B22="","",IFERROR(COUNTIFS(ENVIOS!$F$4:$F$3003,$B22,ENVIOS!$O$4:$O$3003,">0",ENVIOS!$C$4:$C$3003,">="&$E$4,ENVIOS!$C$4:$C$3003,"<="&$G$4)/$D22,"—")) | H22: =IF($B22="","",COUNTIFS(NOVEDADES!$AA$4:$AA$1503,"En plazo",NOVEDADES!$B$4:$B$1503,">="&$E$4,NOVEDADES!$B$4:$B$1503,"<="&$G$4,NOVEDADES!$I$4:$I$1503,$B22)+COUNTIFS(NOVEDADES!$AA$4:$AA$1503,"Por vencer",NOVEDADES!$B$4:$B$1503,">="&$E$4,NOVEDADES!$B$4:$B$1503,"<="&$G$4,NOVEDADES!$I$4:$I$1503,$B22)+COUNTIFS(NOVEDADES!$AA$4:$AA$1503,"Vencida",NOVEDADES!$B$4:$B$1503,">="&$E$4,NOVEDADES!$B$4:$B$1503,"<="&$G$4,NOVEDADES!$I$4:$I$1503,$B22)+COUNTIFS(NOVEDADES!$AA$4:$AA$1503,"Sin clasificar",NOVEDADES!$B$4:$B$1503,">="&$E$4,NOVEDADES!$B$4:$B$1503,"<="&$G$4,NOVEDADES!$I$4:$I$1503,$B22)) | I22: =IF($B22="","",COUNTIFS(NOVEDADES!$I$4:$I$1503,$B22,NOVEDADES!$AA$4:$AA$1503,"Vencida",NOVEDADES!$B$4:$B$1503,">="&$E$4,NOVEDADES!$B$4:$B$1503,"<="&$G$4)) | J22: =IF($B22="","",IFERROR(ROUND(AVERAGEIFS(NOVEDADES!$Z$4:$Z$1503,NOVEDADES!$I$4:$I$1503,$B22,NOVEDADES!$B$4:$B$1503,">="&$E$4,NOVEDADES!$B$4:$B$1503,"<="&$G$4),1),0)) | K22: =IF($B22="","",SUMIFS(NOVEDADES!$U$4:$U$1503,NOVEDADES!$I$4:$I$1503,$B22,NOVEDADES!$B$4:$B$1503,">="&$E$4,NOVEDADES!$B$4:$B$1503,"<="&$G$4)) | L22: =IF(OR($B22="",$D22=0,NOT(ISNUMBER($E22))),"—",ROUND($E22*60+(1-N($G22))*25+IF($F22=0,15,(1-$I22/$F22)*15),0)) | M22: =IF(NOT(ISNUMBER($L22)),"—",IF($L22>=90,"A",IF($L22>=80,"B",IF($L22>=70,"C","D"))))
B23: =IF(CONFIG!$R9="","",CONFIG!$R9) | D23: =IF($B23="","",COUNTIFS(ENVIOS!$F$4:$F$3003,$B23,ENVIOS!$C$4:$C$3003,">="&$E$4,ENVIOS!$C$4:$C$3003,"<="&$G$4)) | E23: =IF($B23="","",IFERROR(COUNTIFS(ENVIOS!$F$4:$F$3003,$B23,ENVIOS!$Q$4:$Q$3003,"OTIF",ENVIOS!$C$4:$C$3003,">="&$E$4,ENVIOS!$C$4:$C$3003,"<="&$G$4)/(COUNTIFS(ENVIOS!$F$4:$F$3003,$B23,ENVIOS!$Q$4:$Q$3003,"OTIF",ENVIOS!$C$4:$C$3003,">="&$E$4,ENVIOS!$C$4:$C$3003,"<="&$G$4)+COUNTIFS(ENVIOS!$F$4:$F$3003,$B23,ENVIOS!$Q$4:$Q$3003,"Falló",ENVIOS!$C$4:$C$3003,">="&$E$4,ENVIOS!$C$4:$C$3003,"<="&$G$4)),"—")) | F23: =IF($B23="","",COUNTIFS(NOVEDADES!$I$4:$I$1503,$B23,NOVEDADES!$B$4:$B$1503,">="&$E$4,NOVEDADES!$B$4:$B$1503,"<="&$G$4)) | G23: =IF($B23="","",IFERROR(COUNTIFS(ENVIOS!$F$4:$F$3003,$B23,ENVIOS!$O$4:$O$3003,">0",ENVIOS!$C$4:$C$3003,">="&$E$4,ENVIOS!$C$4:$C$3003,"<="&$G$4)/$D23,"—")) | H23: =IF($B23="","",COUNTIFS(NOVEDADES!$AA$4:$AA$1503,"En plazo",NOVEDADES!$B$4:$B$1503,">="&$E$4,NOVEDADES!$B$4:$B$1503,"<="&$G$4,NOVEDADES!$I$4:$I$1503,$B23)+COUNTIFS(NOVEDADES!$AA$4:$AA$1503,"Por vencer",NOVEDADES!$B$4:$B$1503,">="&$E$4,NOVEDADES!$B$4:$B$1503,"<="&$G$4,NOVEDADES!$I$4:$I$1503,$B23)+COUNTIFS(NOVEDADES!$AA$4:$AA$1503,"Vencida",NOVEDADES!$B$4:$B$1503,">="&$E$4,NOVEDADES!$B$4:$B$1503,"<="&$G$4,NOVEDADES!$I$4:$I$1503,$B23)+COUNTIFS(NOVEDADES!$AA$4:$AA$1503,"Sin clasificar",NOVEDADES!$B$4:$B$1503,">="&$E$4,NOVEDADES!$B$4:$B$1503,"<="&$G$4,NOVEDADES!$I$4:$I$1503,$B23)) | I23: =IF($B23="","",COUNTIFS(NOVEDADES!$I$4:$I$1503,$B23,NOVEDADES!$AA$4:$AA$1503,"Vencida",NOVEDADES!$B$4:$B$1503,">="&$E$4,NOVEDADES!$B$4:$B$1503,"<="&$G$4)) | J23: =IF($B23="","",IFERROR(ROUND(AVERAGEIFS(NOVEDADES!$Z$4:$Z$1503,NOVEDADES!$I$4:$I$1503,$B23,NOVEDADES!$B$4:$B$1503,">="&$E$4,NOVEDADES!$B$4:$B$1503,"<="&$G$4),1),0)) | K23: =IF($B23="","",SUMIFS(NOVEDADES!$U$4:$U$1503,NOVEDADES!$I$4:$I$1503,$B23,NOVEDADES!$B$4:$B$1503,">="&$E$4,NOVEDADES!$B$4:$B$1503,"<="&$G$4)) | L23: =IF(OR($B23="",$D23=0,NOT(ISNUMBER($E23))),"—",ROUND($E23*60+(1-N($G23))*25+IF($F23=0,15,(1-$I23/$F23)*15),0)) | M23: =IF(NOT(ISNUMBER($L23)),"—",IF($L23>=90,"A",IF($L23>=80,"B",IF($L23>=70,"C","D"))))
B24: =IF(CONFIG!$R10="","",CONFIG!$R10) | D24: =IF($B24="","",COUNTIFS(ENVIOS!$F$4:$F$3003,$B24,ENVIOS!$C$4:$C$3003,">="&$E$4,ENVIOS!$C$4:$C$3003,"<="&$G$4)) | E24: =IF($B24="","",IFERROR(COUNTIFS(ENVIOS!$F$4:$F$3003,$B24,ENVIOS!$Q$4:$Q$3003,"OTIF",ENVIOS!$C$4:$C$3003,">="&$E$4,ENVIOS!$C$4:$C$3003,"<="&$G$4)/(COUNTIFS(ENVIOS!$F$4:$F$3003,$B24,ENVIOS!$Q$4:$Q$3003,"OTIF",ENVIOS!$C$4:$C$3003,">="&$E$4,ENVIOS!$C$4:$C$3003,"<="&$G$4)+COUNTIFS(ENVIOS!$F$4:$F$3003,$B24,ENVIOS!$Q$4:$Q$3003,"Falló",ENVIOS!$C$4:$C$3003,">="&$E$4,ENVIOS!$C$4:$C$3003,"<="&$G$4)),"—")) | F24: =IF($B24="","",COUNTIFS(NOVEDADES!$I$4:$I$1503,$B24,NOVEDADES!$B$4:$B$1503,">="&$E$4,NOVEDADES!$B$4:$B$1503,"<="&$G$4)) | G24: =IF($B24="","",IFERROR(COUNTIFS(ENVIOS!$F$4:$F$3003,$B24,ENVIOS!$O$4:$O$3003,">0",ENVIOS!$C$4:$C$3003,">="&$E$4,ENVIOS!$C$4:$C$3003,"<="&$G$4)/$D24,"—")) | H24: =IF($B24="","",COUNTIFS(NOVEDADES!$AA$4:$AA$1503,"En plazo",NOVEDADES!$B$4:$B$1503,">="&$E$4,NOVEDADES!$B$4:$B$1503,"<="&$G$4,NOVEDADES!$I$4:$I$1503,$B24)+COUNTIFS(NOVEDADES!$AA$4:$AA$1503,"Por vencer",NOVEDADES!$B$4:$B$1503,">="&$E$4,NOVEDADES!$B$4:$B$1503,"<="&$G$4,NOVEDADES!$I$4:$I$1503,$B24)+COUNTIFS(NOVEDADES!$AA$4:$AA$1503,"Vencida",NOVEDADES!$B$4:$B$1503,">="&$E$4,NOVEDADES!$B$4:$B$1503,"<="&$G$4,NOVEDADES!$I$4:$I$1503,$B24)+COUNTIFS(NOVEDADES!$AA$4:$AA$1503,"Sin clasificar",NOVEDADES!$B$4:$B$1503,">="&$E$4,NOVEDADES!$B$4:$B$1503,"<="&$G$4,NOVEDADES!$I$4:$I$1503,$B24)) | I24: =IF($B24="","",COUNTIFS(NOVEDADES!$I$4:$I$1503,$B24,NOVEDADES!$AA$4:$AA$1503,"Vencida",NOVEDADES!$B$4:$B$1503,">="&$E$4,NOVEDADES!$B$4:$B$1503,"<="&$G$4)) | J24: =IF($B24="","",IFERROR(ROUND(AVERAGEIFS(NOVEDADES!$Z$4:$Z$1503,NOVEDADES!$I$4:$I$1503,$B24,NOVEDADES!$B$4:$B$1503,">="&$E$4,NOVEDADES!$B$4:$B$1503,"<="&$G$4),1),0)) | K24: =IF($B24="","",SUMIFS(NOVEDADES!$U$4:$U$1503,NOVEDADES!$I$4:$I$1503,$B24,NOVEDADES!$B$4:$B$1503,">="&$E$4,NOVEDADES!$B$4:$B$1503,"<="&$G$4)) | L24: =IF(OR($B24="",$D24=0,NOT(ISNUMBER($E24))),"—",ROUND($E24*60+(1-N($G24))*25+IF($F24=0,15,(1-$I24/$F24)*15),0)) | M24: =IF(NOT(ISNUMBER($L24)),"—",IF($L24>=90,"A",IF($L24>=80,"B",IF($L24>=70,"C","D"))))
B25: =IF(CONFIG!$R11="","",CONFIG!$R11) | D25: =IF($B25="","",COUNTIFS(ENVIOS!$F$4:$F$3003,$B25,ENVIOS!$C$4:$C$3003,">="&$E$4,ENVIOS!$C$4:$C$3003,"<="&$G$4)) | E25: =IF($B25="","",IFERROR(COUNTIFS(ENVIOS!$F$4:$F$3003,$B25,ENVIOS!$Q$4:$Q$3003,"OTIF",ENVIOS!$C$4:$C$3003,">="&$E$4,ENVIOS!$C$4:$C$3003,"<="&$G$4)/(COUNTIFS(ENVIOS!$F$4:$F$3003,$B25,ENVIOS!$Q$4:$Q$3003,"OTIF",ENVIOS!$C$4:$C$3003,">="&$E$4,ENVIOS!$C$4:$C$3003,"<="&$G$4)+COUNTIFS(ENVIOS!$F$4:$F$3003,$B25,ENVIOS!$Q$4:$Q$3003,"Falló",ENVIOS!$C$4:$C$3003,">="&$E$4,ENVIOS!$C$4:$C$3003,"<="&$G$4)),"—")) | F25: =IF($B25="","",COUNTIFS(NOVEDADES!$I$4:$I$1503,$B25,NOVEDADES!$B$4:$B$1503,">="&$E$4,NOVEDADES!$B$4:$B$1503,"<="&$G$4)) | G25: =IF($B25="","",IFERROR(COUNTIFS(ENVIOS!$F$4:$F$3003,$B25,ENVIOS!$O$4:$O$3003,">0",ENVIOS!$C$4:$C$3003,">="&$E$4,ENVIOS!$C$4:$C$3003,"<="&$G$4)/$D25,"—")) | H25: =IF($B25="","",COUNTIFS(NOVEDADES!$AA$4:$AA$1503,"En plazo",NOVEDADES!$B$4:$B$1503,">="&$E$4,NOVEDADES!$B$4:$B$1503,"<="&$G$4,NOVEDADES!$I$4:$I$1503,$B25)+COUNTIFS(NOVEDADES!$AA$4:$AA$1503,"Por vencer",NOVEDADES!$B$4:$B$1503,">="&$E$4,NOVEDADES!$B$4:$B$1503,"<="&$G$4,NOVEDADES!$I$4:$I$1503,$B25)+COUNTIFS(NOVEDADES!$AA$4:$AA$1503,"Vencida",NOVEDADES!$B$4:$B$1503,">="&$E$4,NOVEDADES!$B$4:$B$1503,"<="&$G$4,NOVEDADES!$I$4:$I$1503,$B25)+COUNTIFS(NOVEDADES!$AA$4:$AA$1503,"Sin clasificar",NOVEDADES!$B$4:$B$1503,">="&$E$4,NOVEDADES!$B$4:$B$1503,"<="&$G$4,NOVEDADES!$I$4:$I$1503,$B25)) | I25: =IF($B25="","",COUNTIFS(NOVEDADES!$I$4:$I$1503,$B25,NOVEDADES!$AA$4:$AA$1503,"Vencida",NOVEDADES!$B$4:$B$1503,">="&$E$4,NOVEDADES!$B$4:$B$1503,"<="&$G$4)) | J25: =IF($B25="","",IFERROR(ROUND(AVERAGEIFS(NOVEDADES!$Z$4:$Z$1503,NOVEDADES!$I$4:$I$1503,$B25,NOVEDADES!$B$4:$B$1503,">="&$E$4,NOVEDADES!$B$4:$B$1503,"<="&$G$4),1),0)) | K25: =IF($B25="","",SUMIFS(NOVEDADES!$U$4:$U$1503,NOVEDADES!$I$4:$I$1503,$B25,NOVEDADES!$B$4:$B$1503,">="&$E$4,NOVEDADES!$B$4:$B$1503,"<="&$G$4)) | L25: =IF(OR($B25="",$D25=0,NOT(ISNUMBER($E25))),"—",ROUND($E25*60+(1-N($G25))*25+IF($F25=0,15,(1-$I25/$F25)*15),0)) | M25: =IF(NOT(ISNUMBER($L25)),"—",IF($L25>=90,"A",IF($L25>=80,"B",IF($L25>=70,"C","D"))))
B26: =IF(CONFIG!$R12="","",CONFIG!$R12) | D26: =IF($B26="","",COUNTIFS(ENVIOS!$F$4:$F$3003,$B26,ENVIOS!$C$4:$C$3003,">="&$E$4,ENVIOS!$C$4:$C$3003,"<="&$G$4)) | E26: =IF($B26="","",IFERROR(COUNTIFS(ENVIOS!$F$4:$F$3003,$B26,ENVIOS!$Q$4:$Q$3003,"OTIF",ENVIOS!$C$4:$C$3003,">="&$E$4,ENVIOS!$C$4:$C$3003,"<="&$G$4)/(COUNTIFS(ENVIOS!$F$4:$F$3003,$B26,ENVIOS!$Q$4:$Q$3003,"OTIF",ENVIOS!$C$4:$C$3003,">="&$E$4,ENVIOS!$C$4:$C$3003,"<="&$G$4)+COUNTIFS(ENVIOS!$F$4:$F$3003,$B26,ENVIOS!$Q$4:$Q$3003,"Falló",ENVIOS!$C$4:$C$3003,">="&$E$4,ENVIOS!$C$4:$C$3003,"<="&$G$4)),"—")) | F26: =IF($B26="","",COUNTIFS(NOVEDADES!$I$4:$I$1503,$B26,NOVEDADES!$B$4:$B$1503,">="&$E$4,NOVEDADES!$B$4:$B$1503,"<="&$G$4)) | G26: =IF($B26="","",IFERROR(COUNTIFS(ENVIOS!$F$4:$F$3003,$B26,ENVIOS!$O$4:$O$3003,">0",ENVIOS!$C$4:$C$3003,">="&$E$4,ENVIOS!$C$4:$C$3003,"<="&$G$4)/$D26,"—")) | H26: =IF($B26="","",COUNTIFS(NOVEDADES!$AA$4:$AA$1503,"En plazo",NOVEDADES!$B$4:$B$1503,">="&$E$4,NOVEDADES!$B$4:$B$1503,"<="&$G$4,NOVEDADES!$I$4:$I$1503,$B26)+COUNTIFS(NOVEDADES!$AA$4:$AA$1503,"Por vencer",NOVEDADES!$B$4:$B$1503,">="&$E$4,NOVEDADES!$B$4:$B$1503,"<="&$G$4,NOVEDADES!$I$4:$I$1503,$B26)+COUNTIFS(NOVEDADES!$AA$4:$AA$1503,"Vencida",NOVEDADES!$B$4:$B$1503,">="&$E$4,NOVEDADES!$B$4:$B$1503,"<="&$G$4,NOVEDADES!$I$4:$I$1503,$B26)+COUNTIFS(NOVEDADES!$AA$4:$AA$1503,"Sin clasificar",NOVEDADES!$B$4:$B$1503,">="&$E$4,NOVEDADES!$B$4:$B$1503,"<="&$G$4,NOVEDADES!$I$4:$I$1503,$B26)) | I26: =IF($B26="","",COUNTIFS(NOVEDADES!$I$4:$I$1503,$B26,NOVEDADES!$AA$4:$AA$1503,"Vencida",NOVEDADES!$B$4:$B$1503,">="&$E$4,NOVEDADES!$B$4:$B$1503,"<="&$G$4)) | J26: =IF($B26="","",IFERROR(ROUND(AVERAGEIFS(NOVEDADES!$Z$4:$Z$1503,NOVEDADES!$I$4:$I$1503,$B26,NOVEDADES!$B$4:$B$1503,">="&$E$4,NOVEDADES!$B$4:$B$1503,"<="&$G$4),1),0)) | K26: =IF($B26="","",SUMIFS(NOVEDADES!$U$4:$U$1503,NOVEDADES!$I$4:$I$1503,$B26,NOVEDADES!$B$4:$B$1503,">="&$E$4,NOVEDADES!$B$4:$B$1503,"<="&$G$4)) | L26: =IF(OR($B26="",$D26=0,NOT(ISNUMBER($E26))),"—",ROUND($E26*60+(1-N($G26))*25+IF($F26=0,15,(1-$I26/$F26)*15),0)) | M26: =IF(NOT(ISNUMBER($L26)),"—",IF($L26>=90,"A",IF($L26>=80,"B",IF($L26>=70,"C","D"))))
B27: =IF(CONFIG!$R13="","",CONFIG!$R13) | D27: =IF($B27="","",COUNTIFS(ENVIOS!$F$4:$F$3003,$B27,ENVIOS!$C$4:$C$3003,">="&$E$4,ENVIOS!$C$4:$C$3003,"<="&$G$4)) | E27: =IF($B27="","",IFERROR(COUNTIFS(ENVIOS!$F$4:$F$3003,$B27,ENVIOS!$Q$4:$Q$3003,"OTIF",ENVIOS!$C$4:$C$3003,">="&$E$4,ENVIOS!$C$4:$C$3003,"<="&$G$4)/(COUNTIFS(ENVIOS!$F$4:$F$3003,$B27,ENVIOS!$Q$4:$Q$3003,"OTIF",ENVIOS!$C$4:$C$3003,">="&$E$4,ENVIOS!$C$4:$C$3003,"<="&$G$4)+COUNTIFS(ENVIOS!$F$4:$F$3003,$B27,ENVIOS!$Q$4:$Q$3003,"Falló",ENVIOS!$C$4:$C$3003,">="&$E$4,ENVIOS!$C$4:$C$3003,"<="&$G$4)),"—")) | F27: =IF($B27="","",COUNTIFS(NOVEDADES!$I$4:$I$1503,$B27,NOVEDADES!$B$4:$B$1503,">="&$E$4,NOVEDADES!$B$4:$B$1503,"<="&$G$4)) | G27: =IF($B27="","",IFERROR(COUNTIFS(ENVIOS!$F$4:$F$3003,$B27,ENVIOS!$O$4:$O$3003,">0",ENVIOS!$C$4:$C$3003,">="&$E$4,ENVIOS!$C$4:$C$3003,"<="&$G$4)/$D27,"—")) | H27: =IF($B27="","",COUNTIFS(NOVEDADES!$AA$4:$AA$1503,"En plazo",NOVEDADES!$B$4:$B$1503,">="&$E$4,NOVEDADES!$B$4:$B$1503,"<="&$G$4,NOVEDADES!$I$4:$I$1503,$B27)+COUNTIFS(NOVEDADES!$AA$4:$AA$1503,"Por vencer",NOVEDADES!$B$4:$B$1503,">="&$E$4,NOVEDADES!$B$4:$B$1503,"<="&$G$4,NOVEDADES!$I$4:$I$1503,$B27)+COUNTIFS(NOVEDADES!$AA$4:$AA$1503,"Vencida",NOVEDADES!$B$4:$B$1503,">="&$E$4,NOVEDADES!$B$4:$B$1503,"<="&$G$4,NOVEDADES!$I$4:$I$1503,$B27)+COUNTIFS(NOVEDADES!$AA$4:$AA$1503,"Sin clasificar",NOVEDADES!$B$4:$B$1503,">="&$E$4,NOVEDADES!$B$4:$B$1503,"<="&$G$4,NOVEDADES!$I$4:$I$1503,$B27)) | I27: =IF($B27="","",COUNTIFS(NOVEDADES!$I$4:$I$1503,$B27,NOVEDADES!$AA$4:$AA$1503,"Vencida",NOVEDADES!$B$4:$B$1503,">="&$E$4,NOVEDADES!$B$4:$B$1503,"<="&$G$4)) | J27: =IF($B27="","",IFERROR(ROUND(AVERAGEIFS(NOVEDADES!$Z$4:$Z$1503,NOVEDADES!$I$4:$I$1503,$B27,NOVEDADES!$B$4:$B$1503,">="&$E$4,NOVEDADES!$B$4:$B$1503,"<="&$G$4),1),0)) | K27: =IF($B27="","",SUMIFS(NOVEDADES!$U$4:$U$1503,NOVEDADES!$I$4:$I$1503,$B27,NOVEDADES!$B$4:$B$1503,">="&$E$4,NOVEDADES!$B$4:$B$1503,"<="&$G$4)) | L27: =IF(OR($B27="",$D27=0,NOT(ISNUMBER($E27))),"—",ROUND($E27*60+(1-N($G27))*25+IF($F27=0,15,(1-$I27/$F27)*15),0)) | M27: =IF(NOT(ISNUMBER($L27)),"—",IF($L27>=90,"A",IF($L27>=80,"B",IF($L27>=70,"C","D"))))
B28: ="TOTAL" | D28: =SUM($D$18:$D$27) | E28: =IFERROR(COUNTIFS(ENVIOS!$Q$4:$Q$3003,"OTIF",ENVIOS!$C$4:$C$3003,">="&$E$4,ENVIOS!$C$4:$C$3003,"<="&$G$4)/(COUNTIFS(ENVIOS!$Q$4:$Q$3003,"OTIF",ENVIOS!$C$4:$C$3003,">="&$E$4,ENVIOS!$C$4:$C$3003,"<="&$G$4)+COUNTIFS(ENVIOS!$Q$4:$Q$3003,"Falló",ENVIOS!$C$4:$C$3003,">="&$E$4,ENVIOS!$C$4:$C$3003,"<="&$G$4)),"—") | F28: =SUM($F$18:$F$27) | G28: =IFERROR(COUNTIFS(ENVIOS!$O$4:$O$3003,">0",ENVIOS!$C$4:$C$3003,">="&$E$4,ENVIOS!$C$4:$C$3003,"<="&$G$4)/COUNTIFS(ENVIOS!$C$4:$C$3003,">="&$E$4,ENVIOS!$C$4:$C$3003,"<="&$G$4),"—") | H28: =SUM($H$18:$H$27) | I28: =SUM($I$18:$I$27) | J28: =IFERROR(ROUND(AVERAGEIFS(NOVEDADES!$Z$4:$Z$1503,NOVEDADES!$C$4:$C$1503,"En ruta",NOVEDADES!$B$4:$B$1503,">="&$E$4,NOVEDADES!$B$4:$B$1503,"<="&$G$4),1),0) | K28: =SUM($K$18:$K$27)
B30: 2 · PARETO DE CAUSA RAÍZ — dónde atacar primero
B31: Regla 80/20: las causas que aparecen hasta llegar a 80% en la columna «% acumulado» son las que explican casi todas sus novedades. Empiece por ahí. Incluye en ruta e internas.
B32: Causa raíz | D32: Casos | E32: % de las novedades | F32: % acumulado | G32: Valor afectado | H32: Familia (6M) | I32: Área responsable
B33: =IFERROR(INDEX(CONFIG!$G$4:$G$33,MATCH(LARGE(CONFIG!$V$4:$V$33,1),CONFIG!$V$4:$V$33,0)),"") | D33: =IF($B33="","",ROUNDDOWN(LARGE(CONFIG!$V$4:$V$33,1),0)) | E33: =IF($B33="","",IFERROR($D33/$D$45,0)) | F33: =IF($B33="","",IFERROR(SUM($D$33:$D33)/$D$45,0)) | G33: =IF($B33="","",SUMIFS(NOVEDADES!$U$4:$U$1503,NOVEDADES!$Q$4:$Q$1503,$B33,NOVEDADES!$B$4:$B$1503,">="&$E$4,NOVEDADES!$B$4:$B$1503,"<="&$G$4)) | H33: =IF($B33="","",IFERROR(INDEX(CONFIG!$H$4:$H$63,MATCH($B33,CONFIG!$G$4:$G$63,0)),"")) | I33: =IF($B33="","",IFERROR(INDEX(CONFIG!$I$4:$I$63,MATCH($B33,CONFIG!$G$4:$G$63,0)),""))
B34: =IFERROR(INDEX(CONFIG!$G$4:$G$33,MATCH(LARGE(CONFIG!$V$4:$V$33,2),CONFIG!$V$4:$V$33,0)),"") | D34: =IF($B34="","",ROUNDDOWN(LARGE(CONFIG!$V$4:$V$33,2),0)) | E34: =IF($B34="","",IFERROR($D34/$D$45,0)) | F34: =IF($B34="","",IFERROR(SUM($D$33:$D34)/$D$45,0)) | G34: =IF($B34="","",SUMIFS(NOVEDADES!$U$4:$U$1503,NOVEDADES!$Q$4:$Q$1503,$B34,NOVEDADES!$B$4:$B$1503,">="&$E$4,NOVEDADES!$B$4:$B$1503,"<="&$G$4)) | H34: =IF($B34="","",IFERROR(INDEX(CONFIG!$H$4:$H$63,MATCH($B34,CONFIG!$G$4:$G$63,0)),"")) | I34: =IF($B34="","",IFERROR(INDEX(CONFIG!$I$4:$I$63,MATCH($B34,CONFIG!$G$4:$G$63,0)),""))
B35: =IFERROR(INDEX(CONFIG!$G$4:$G$33,MATCH(LARGE(CONFIG!$V$4:$V$33,3),CONFIG!$V$4:$V$33,0)),"") | D35: =IF($B35="","",ROUNDDOWN(LARGE(CONFIG!$V$4:$V$33,3),0)) | E35: =IF($B35="","",IFERROR($D35/$D$45,0)) | F35: =IF($B35="","",IFERROR(SUM($D$33:$D35)/$D$45,0)) | G35: =IF($B35="","",SUMIFS(NOVEDADES!$U$4:$U$1503,NOVEDADES!$Q$4:$Q$1503,$B35,NOVEDADES!$B$4:$B$1503,">="&$E$4,NOVEDADES!$B$4:$B$1503,"<="&$G$4)) | H35: =IF($B35="","",IFERROR(INDEX(CONFIG!$H$4:$H$63,MATCH($B35,CONFIG!$G$4:$G$63,0)),"")) | I35: =IF($B35="","",IFERROR(INDEX(CONFIG!$I$4:$I$63,MATCH($B35,CONFIG!$G$4:$G$63,0)),""))
B36: =IFERROR(INDEX(CONFIG!$G$4:$G$33,MATCH(LARGE(CONFIG!$V$4:$V$33,4),CONFIG!$V$4:$V$33,0)),"") | D36: =IF($B36="","",ROUNDDOWN(LARGE(CONFIG!$V$4:$V$33,4),0)) | E36: =IF($B36="","",IFERROR($D36/$D$45,0)) | F36: =IF($B36="","",IFERROR(SUM($D$33:$D36)/$D$45,0)) | G36: =IF($B36="","",SUMIFS(NOVEDADES!$U$4:$U$1503,NOVEDADES!$Q$4:$Q$1503,$B36,NOVEDADES!$B$4:$B$1503,">="&$E$4,NOVEDADES!$B$4:$B$1503,"<="&$G$4)) | H36: =IF($B36="","",IFERROR(INDEX(CONFIG!$H$4:$H$63,MATCH($B36,CONFIG!$G$4:$G$63,0)),"")) | I36: =IF($B36="","",IFERROR(INDEX(CONFIG!$I$4:$I$63,MATCH($B36,CONFIG!$G$4:$G$63,0)),""))
B37: =IFERROR(INDEX(CONFIG!$G$4:$G$33,MATCH(LARGE(CONFIG!$V$4:$V$33,5),CONFIG!$V$4:$V$33,0)),"") | D37: =IF($B37="","",ROUNDDOWN(LARGE(CONFIG!$V$4:$V$33,5),0)) | E37: =IF($B37="","",IFERROR($D37/$D$45,0)) | F37: =IF($B37="","",IFERROR(SUM($D$33:$D37)/$D$45,0)) | G37: =IF($B37="","",SUMIFS(NOVEDADES!$U$4:$U$1503,NOVEDADES!$Q$4:$Q$1503,$B37,NOVEDADES!$B$4:$B$1503,">="&$E$4,NOVEDADES!$B$4:$B$1503,"<="&$G$4)) | H37: =IF($B37="","",IFERROR(INDEX(CONFIG!$H$4:$H$63,MATCH($B37,CONFIG!$G$4:$G$63,0)),"")) | I37: =IF($B37="","",IFERROR(INDEX(CONFIG!$I$4:$I$63,MATCH($B37,CONFIG!$G$4:$G$63,0)),""))
B38: =IFERROR(INDEX(CONFIG!$G$4:$G$33,MATCH(LARGE(CONFIG!$V$4:$V$33,6),CONFIG!$V$4:$V$33,0)),"") | D38: =IF($B38="","",ROUNDDOWN(LARGE(CONFIG!$V$4:$V$33,6),0)) | E38: =IF($B38="","",IFERROR($D38/$D$45,0)) | F38: =IF($B38="","",IFERROR(SUM($D$33:$D38)/$D$45,0)) | G38: =IF($B38="","",SUMIFS(NOVEDADES!$U$4:$U$1503,NOVEDADES!$Q$4:$Q$1503,$B38,NOVEDADES!$B$4:$B$1503,">="&$E$4,NOVEDADES!$B$4:$B$1503,"<="&$G$4)) | H38: =IF($B38="","",IFERROR(INDEX(CONFIG!$H$4:$H$63,MATCH($B38,CONFIG!$G$4:$G$63,0)),"")) | I38: =IF($B38="","",IFERROR(INDEX(CONFIG!$I$4:$I$63,MATCH($B38,CONFIG!$G$4:$G$63,0)),""))
B39: =IFERROR(INDEX(CONFIG!$G$4:$G$33,MATCH(LARGE(CONFIG!$V$4:$V$33,7),CONFIG!$V$4:$V$33,0)),"") | D39: =IF($B39="","",ROUNDDOWN(LARGE(CONFIG!$V$4:$V$33,7),0)) | E39: =IF($B39="","",IFERROR($D39/$D$45,0)) | F39: =IF($B39="","",IFERROR(SUM($D$33:$D39)/$D$45,0)) | G39: =IF($B39="","",SUMIFS(NOVEDADES!$U$4:$U$1503,NOVEDADES!$Q$4:$Q$1503,$B39,NOVEDADES!$B$4:$B$1503,">="&$E$4,NOVEDADES!$B$4:$B$1503,"<="&$G$4)) | H39: =IF($B39="","",IFERROR(INDEX(CONFIG!$H$4:$H$63,MATCH($B39,CONFIG!$G$4:$G$63,0)),"")) | I39: =IF($B39="","",IFERROR(INDEX(CONFIG!$I$4:$I$63,MATCH($B39,CONFIG!$G$4:$G$63,0)),""))
B40: =IFERROR(INDEX(CONFIG!$G$4:$G$33,MATCH(LARGE(CONFIG!$V$4:$V$33,8),CONFIG!$V$4:$V$33,0)),"") | D40: =IF($B40="","",ROUNDDOWN(LARGE(CONFIG!$V$4:$V$33,8),0)) | E40: =IF($B40="","",IFERROR($D40/$D$45,0)) | F40: =IF($B40="","",IFERROR(SUM($D$33:$D40)/$D$45,0)) | G40: =IF($B40="","",SUMIFS(NOVEDADES!$U$4:$U$1503,NOVEDADES!$Q$4:$Q$1503,$B40,NOVEDADES!$B$4:$B$1503,">="&$E$4,NOVEDADES!$B$4:$B$1503,"<="&$G$4)) | H40: =IF($B40="","",IFERROR(INDEX(CONFIG!$H$4:$H$63,MATCH($B40,CONFIG!$G$4:$G$63,0)),"")) | I40: =IF($B40="","",IFERROR(INDEX(CONFIG!$I$4:$I$63,MATCH($B40,CONFIG!$G$4:$G$63,0)),""))
B41: =IFERROR(INDEX(CONFIG!$G$4:$G$33,MATCH(LARGE(CONFIG!$V$4:$V$33,9),CONFIG!$V$4:$V$33,0)),"") | D41: =IF($B41="","",ROUNDDOWN(LARGE(CONFIG!$V$4:$V$33,9),0)) | E41: =IF($B41="","",IFERROR($D41/$D$45,0)) | F41: =IF($B41="","",IFERROR(SUM($D$33:$D41)/$D$45,0)) | G41: =IF($B41="","",SUMIFS(NOVEDADES!$U$4:$U$1503,NOVEDADES!$Q$4:$Q$1503,$B41,NOVEDADES!$B$4:$B$1503,">="&$E$4,NOVEDADES!$B$4:$B$1503,"<="&$G$4)) | H41: =IF($B41="","",IFERROR(INDEX(CONFIG!$H$4:$H$63,MATCH($B41,CONFIG!$G$4:$G$63,0)),"")) | I41: =IF($B41="","",IFERROR(INDEX(CONFIG!$I$4:$I$63,MATCH($B41,CONFIG!$G$4:$G$63,0)),""))
B42: =IFERROR(INDEX(CONFIG!$G$4:$G$33,MATCH(LARGE(CONFIG!$V$4:$V$33,10),CONFIG!$V$4:$V$33,0)),"") | D42: =IF($B42="","",ROUNDDOWN(LARGE(CONFIG!$V$4:$V$33,10),0)) | E42: =IF($B42="","",IFERROR($D42/$D$45,0)) | F42: =IF($B42="","",IFERROR(SUM($D$33:$D42)/$D$45,0)) | G42: =IF($B42="","",SUMIFS(NOVEDADES!$U$4:$U$1503,NOVEDADES!$Q$4:$Q$1503,$B42,NOVEDADES!$B$4:$B$1503,">="&$E$4,NOVEDADES!$B$4:$B$1503,"<="&$G$4)) | H42: =IF($B42="","",IFERROR(INDEX(CONFIG!$H$4:$H$63,MATCH($B42,CONFIG!$G$4:$G$63,0)),"")) | I42: =IF($B42="","",IFERROR(INDEX(CONFIG!$I$4:$I$63,MATCH($B42,CONFIG!$G$4:$G$63,0)),""))
B43: =IFERROR(INDEX(CONFIG!$G$4:$G$33,MATCH(LARGE(CONFIG!$V$4:$V$33,11),CONFIG!$V$4:$V$33,0)),"") | D43: =IF($B43="","",ROUNDDOWN(LARGE(CONFIG!$V$4:$V$33,11),0)) | E43: =IF($B43="","",IFERROR($D43/$D$45,0)) | F43: =IF($B43="","",IFERROR(SUM($D$33:$D43)/$D$45,0)) | G43: =IF($B43="","",SUMIFS(NOVEDADES!$U$4:$U$1503,NOVEDADES!$Q$4:$Q$1503,$B43,NOVEDADES!$B$4:$B$1503,">="&$E$4,NOVEDADES!$B$4:$B$1503,"<="&$G$4)) | H43: =IF($B43="","",IFERROR(INDEX(CONFIG!$H$4:$H$63,MATCH($B43,CONFIG!$G$4:$G$63,0)),"")) | I43: =IF($B43="","",IFERROR(INDEX(CONFIG!$I$4:$I$63,MATCH($B43,CONFIG!$G$4:$G$63,0)),""))
B44: =IFERROR(INDEX(CONFIG!$G$4:$G$33,MATCH(LARGE(CONFIG!$V$4:$V$33,12),CONFIG!$V$4:$V$33,0)),"") | D44: =IF($B44="","",ROUNDDOWN(LARGE(CONFIG!$V$4:$V$33,12),0)) | E44: =IF($B44="","",IFERROR($D44/$D$45,0)) | F44: =IF($B44="","",IFERROR(SUM($D$33:$D44)/$D$45,0)) | G44: =IF($B44="","",SUMIFS(NOVEDADES!$U$4:$U$1503,NOVEDADES!$Q$4:$Q$1503,$B44,NOVEDADES!$B$4:$B$1503,">="&$E$4,NOVEDADES!$B$4:$B$1503,"<="&$G$4)) | H44: =IF($B44="","",IFERROR(INDEX(CONFIG!$H$4:$H$63,MATCH($B44,CONFIG!$G$4:$G$63,0)),"")) | I44: =IF($B44="","",IFERROR(INDEX(CONFIG!$I$4:$I$63,MATCH($B44,CONFIG!$G$4:$G$63,0)),""))
B45: ="TOTAL de novedades del periodo" | D45: =COUNTIFS(NOVEDADES!$B$4:$B$1503,">="&$E$4,NOVEDADES!$B$4:$B$1503,"<="&$G$4) | E45: =IF($D$45=0,0,1) | G45: =SUMIFS(NOVEDADES!$U$4:$U$1503,NOVEDADES!$B$4:$B$1503,">="&$E$4,NOVEDADES!$B$4:$B$1503,"<="&$G$4)
B47: 3 · NOVEDADES POR TIPO — qué está pasando
...

Sheet NOVEDADES
A1: MATRIZ DE NOVEDADES · logística y transporte
A2: ① IDENTIFICAR · fecha y origen siempre; el Nº de guía solo si la novedad fue en ruta | M2: ② CLASIFICAR · qué pasó, dónde y por qué | T2: ③ IMPACTO | V2: ④ GESTIONAR Y CERRAR | AB2: ⑤ CONSTANCIA
A3: ID | B3: Fecha de la novedad | C3: Origen | D3: Nº Guía / Remisión | E3: Validación | F3: Nº Pedido | G3: Cliente | H3: Ciudad destino | I3: Transportadora | J3: Conductor | K3: Placa | L3: Fecha despacho | M3: Tipo de novedad | N3: Gravedad | O3: ¿Afecta la entrega? | P3: Punto de ocurrencia | Q3: Causa raíz | R3: Familia (6M) | S3: Área responsable | T3: Unidades afectadas | U3: Valor afectado | V3: Estado | W3: Responsable | X3: Fecha límite | Y3: Fecha de solución | Z3: Días abiertos | AA3: Estado SLA | AB3: Qué se hizo | AC3: Notas / soporte
A4: =IF($B4="","","N-"&TEXT(ROW()-3,"0000")) | B4: 46247 | C4: En ruta | D4: G-2403 | E4: =IF($C4="","",IF($D4="",IF($C4="Interna","Sin guía (interna)","FALTA GUÍA"),IF(COUNTIFS(ENVIOS!$A$4:$A$3003,$D4)=0,"NO EXISTE",IF(COUNTIFS(ENVIOS!$A$4:$A$3003,$D4)>1,"DUPLICADA","OK")))) | F4: =IF($D4="","",IFERROR(INDEX(ENVIOS!$B$4:$B$3003,MATCH($D4,ENVIOS!$A$4:$A$3003,0)),"—")) | G4: =IF($D4="","",IFERROR(INDEX(ENVIOS!$D$4:$D$3003,MATCH($D4,ENVIOS!$A$4:$A$3003,0)),"—")) | H4: =IF($D4="","",IFERROR(INDEX(ENVIOS!$E$4:$E$3003,MATCH($D4,ENVIOS!$A$4:$A$3003,0)),"—")) | I4: =IF($D4="","",IFERROR(INDEX(ENVIOS!$F$4:$F$3003,MATCH($D4,ENVIOS!$A$4:$A$3003,0)),"—")) | J4: =IF($D4="","",IFERROR(INDEX(ENVIOS!$G$4:$G$3003,MATCH($D4,ENVIOS!$A$4:$A$3003,0)),"—")) | K4: =IF($D4="","",IFERROR(INDEX(ENVIOS!$H$4:$H$3003,MATCH($D4,ENVIOS!$A$4:$A$3003,0)),"—")) | L4: =IF($D4="","",IFERROR(INDEX(ENVIOS!$C$4:$C$3003,MATCH($D4,ENVIOS!$A$4:$A$3003,0)),"")) | M4: Empaque en mal estado | N4: =IF($M4="","",IFERROR(INDEX(CONFIG!$C$4:$C$63,MATCH($M4,CONFIG!$A$4:$A$63,0)),"Media")) | O4: =IF($M4="","",IF($C4="Interna","NO",IFERROR(INDEX(CONFIG!$E$4:$E$63,MATCH($M4,CONFIG!$A$4:$A$63,0)),"NO"))) | P4: En ruta / entrega al cliente | Q4: Embalaje o estibado deficiente | R4: =IF($Q4="","",IFERROR(INDEX(CONFIG!$H$4:$H$63,MATCH($Q4,CONFIG!$G$4:$G$63,0)),"Por definir")) | S4: =IF($Q4="","",IFERROR(INDEX(CONFIG!$I$4:$I$63,MATCH($Q4,CONFIG!$G$4:$G$63,0)),"Por definir")) | T4: 1 | U4: 0 | V4: Resuelta | W4: Jefe de bodega | X4: =IF(OR($B4="",$M4=""),"",WORKDAY($B4,IFERROR(INDEX(CONFIG!$D$4:$D$63,MATCH($M4,CONFIG!$A$4:$A$63,0)),3))) | Y4: 46248 | Z4: =IF($B4="","",IF($Y4<>"",$Y4-$B4,TODAY()-$B4)) | AA4: =IF($B4="","",IF(IFERROR(INDEX(CONFIG!$L$4:$L$63,MATCH($V4,CONFIG!$K$4:$K$63,0)),"NO")="SÍ",IF(OR($Y4="",$X4=""),"Resuelta",IF($Y4>$X4,"Resuelta tarde","Resuelta a tiempo")),IF($X4="","Sin clasificar",IF(TODAY()>$X4,"Vencida",IF(TODAY()>=$X4-1,"Por vencer","En plazo"))))) | AB4: Se cambió el empaque y se reforzó el estibado
A5: =IF($B5="","","N-"&TEXT(ROW()-3,"0000")) | B5: 46252 | C5: En ruta | D5: G-2410 | E5: =IF($C5="","",IF($D5="",IF($C5="Interna","Sin guía (interna)","FALTA GUÍA"),IF(COUNTIFS(ENVIOS!$A$4:$A$3003,$D5)=0,"NO EXISTE",IF(COUNTIFS(ENVIOS!$A$4:$A$3003,$D5)>1,"DUPLICADA","OK")))) | F5: =IF($D5="","",IFERROR(INDEX(ENVIOS!$B$4:$B$3003,MATCH($D5,ENVIOS!$A$4:$A$3003,0)),"—")) | G5: =IF($D5="","",IFERROR(INDEX(ENVIOS!$D$4:$D$3003,MATCH($D5,ENVIOS!$A$4:$A$3003,0)),"—")) | H5: =IF($D5="","",IFERROR(INDEX(ENVIOS!$E$4:$E$3003,MATCH($D5,ENVIOS!$A$4:$A$3003,0)),"—")) | I5: =IF($D5="","",IFERROR(INDEX(ENVIOS!$F$4:$F$3003,MATCH($D5,ENVIOS!$A$4:$A$3003,0)),"—")) | J5: =IF($D5="","",IFERROR(INDEX(ENVIOS!$G$4:$G$3003,MATCH($D5,ENVIOS!$A$4:$A$3003,0)),"—")) | K5: =IF($D5="","",IFERROR(INDEX(ENVIOS!$H$4:$H$3003,MATCH($D5,ENVIOS!$A$4:$A$3003,0)),"—")) | L5: =IF($D5="","",IFERROR(INDEX(ENVIOS!$C$4:$C$3003,MATCH($D5,ENVIOS!$A$4:$A$3003,0)),"")) | M5: Retraso en vía | N5: =IF($M5="","",IFERROR(INDEX(CONFIG!$C$4:$C$63,MATCH($M5,CONFIG!$A$4:$A$63,0)),"Media")) | O5: =IF($M5="","",IF($C5="Interna","NO",IFERROR(INDEX(CONFIG!$E$4:$E$63,MATCH($M5,CONFIG!$A$4:$A$63,0)),"NO"))) | P5: En ruta / entrega al cliente | Q5: Tráfico, cierre vial u orden público | R5: =IF($Q5="","",IFERROR(INDEX(CONFIG!$H$4:$H$63,MATCH($Q5,CONFIG!$G$4:$G$63,0)),"Por definir")) | S5: =IF($Q5="","",IFERROR(INDEX(CONFIG!$I$4:$I$63,MATCH($Q5,CONFIG!$G$4:$G$63,0)),"Por definir")) | T5: 0 | U5: 0 | V5: Resuelta | W5: Analista de transporte | X5: =IF(OR($B5="",$M5=""),"",WORKDAY($B5,IFERROR(INDEX(CONFIG!$D$4:$D$63,MATCH($M5,CONFIG!$A$4:$A$63,0)),3))) | Y5: 46253 | Z5: =IF($B5="","",IF($Y5<>"",$Y5-$B5,TODAY()-$B5)) | AA5: =IF($B5="","",IF(IFERROR(INDEX(CONFIG!$L$4:$L$63,MATCH($V5,CONFIG!$K$4:$K$63,0)),"NO")="SÍ",IF(OR($Y5="",$X5=""),"Resuelta",IF($Y5>$X5,"Resuelta tarde","Resuelta a tiempo")),IF($X5="","Sin clasificar",IF(TODAY()>$X5,"Vencida",IF(TODAY()>=$X5-1,"Por vencer","En plazo"))))) | AB5: Cierre en La Línea; se reprogramó la ruta
A6: =IF($B6="","","N-"&TEXT(ROW()-3,"0000")) | B6: 46254 | C6: En ruta | D6: G-2417 | E6: =IF($C6="","",IF($D6="",IF($C6="Interna","Sin guía (interna)","FALTA GUÍA"),IF(COUNTIFS(ENVIOS!$A$4:$A$3003,$D6)=0,"NO EXISTE",IF(COUNTIFS(ENVIOS!$A$4:$A$3003,$D6)>1,"DUPLICADA","OK")))) | F6: =IF($D6="","",IFERROR(INDEX(ENVIOS!$B$4:$B$3003,MATCH($D6,ENVIOS!$A$4:$A$3003,0)),"—")) | G6: =IF($D6="","",IFERROR(INDEX(ENVIOS!$D$4:$D$3003,MATCH($D6,ENVIOS!$A$4:$A$3003,0)),"—")) | H6: =IF($D6="","",IFERROR(INDEX(ENVIOS!$E$4:$E$3003,MATCH($D6,ENVIOS!$A$4:$A$3003,0)),"—")) | I6: =IF($D6="","",IFERROR(INDEX(ENVIOS!$F$4:$F$3003,MATCH($D6,ENVIOS!$A$4:$A$3003,0)),"—")) | J6: =IF($D6="","",IFERROR(INDEX(ENVIOS!$G$4:$G$3003,MATCH($D6,ENVIOS!$A$4:$A$3003,0)),"—")) | K6: =IF($D6="","",IFERROR(INDEX(ENVIOS!$H$4:$H$3003,MATCH($D6,ENVIOS!$A$4:$A$3003,0)),"—")) | L6: =IF($D6="","",IFERROR(INDEX(ENVIOS!$C$4:$C$3003,MATCH($D6,ENVIOS!$A$4:$A$3003,0)),"")) | M6: Avería / producto dañado | N6: =IF($M6="","",IFERROR(INDEX(CONFIG!$C$4:$C$63,MATCH($M6,CONFIG!$A$4:$A$63,0)),"Media")) | O6: =IF($M6="","",IF($C6="Interna","NO",IFERROR(INDEX(CONFIG!$E$4:$E$63,MATCH($M6,CONFIG!$A$4:$A$63,0)),"NO"))) | P6: En ruta / entrega al cliente | Q6: Manipulación brusca en cargue/descargue | R6: =IF($Q6="","",IFERROR(INDEX(CONFIG!$H$4:$H$63,MATCH($Q6,CONFIG!$G$4:$G$63,0)),"Por definir")) | S6: =IF($Q6="","",IFERROR(INDEX(CONFIG!$I$4:$I$63,MATCH($Q6,CONFIG!$G$4:$G$63,0)),"Por definir")) | T6: 4 | U6: 1380000 | V6: Resuelta | W6: Coordinador de logística | X6: =IF(OR($B6="",$M6=""),"",WORKDAY($B6,IFERROR(INDEX(CONFIG!$D$4:$D$63,MATCH($M6,CONFIG!$A$4:$A$63,0)),3))) | Y6: 46259 | Z6: =IF($B6="","",IF($Y6<>"",$Y6-$B6,TODAY()-$B6)) | AA6: =IF($B6="","",IF(IFERROR(INDEX(CONFIG!$L$4:$L$63,MATCH($V6,CONFIG!$K$4:$K$63,0)),"NO")="SÍ",IF(OR($Y6="",$X6=""),"Resuelta",IF($Y6>$X6,"Resuelta tarde","Resuelta a tiempo")),IF($X6="","Sin clasificar",IF(TODAY()>$X6,"Vencida",IF(TODAY()>=$X6-1,"Por vencer","En plazo"))))) | AB6: Nota crédito y recobro a la transportadora | AC6: Se pidió reinducción al equipo de cargue
A7: =IF($B7="","","N-"&TEXT(ROW()-3,"0000")) | B7: 46254 | C7: En ruta | D7: G-2417 | E7: =IF($C7="","",IF($D7="",IF($C7="Interna","Sin guía (interna)","FALTA GUÍA"),IF(COUNTIFS(ENVIOS!$A$4:$A$3003,$D7)=0,"NO EXISTE",IF(COUNTIFS(ENVIOS!$A$4:$A$3003,$D7)>1,"DUPLICADA","OK")))) | F7: =IF($D7="","",IFERROR(INDEX(ENVIOS!$B$4:$B$3003,MATCH($D7,ENVIOS!$A$4:$A$3003,0)),"—")) | G7: =IF($D7="","",IFERROR(INDEX(ENVIOS!$D$4:$D$3003,MATCH($D7,ENVIOS!$A$4:$A$3003,0)),"—")) | H7: =IF($D7="","",IFERROR(INDEX(ENVIOS!$E$4:$E$3003,MATCH($D7,ENVIOS!$A$4:$A$3003,0)),"—")) | I7: =IF($D7="","",IFERROR(INDEX(ENVIOS!$F$4:$F$3003,MATCH($D7,ENVIOS!$A$4:$A$3003,0)),"—")) | J7: =IF($D7="","",IFERROR(INDEX(ENVIOS!$G$4:$G$3003,MATCH($D7,ENVIOS!$A$4:$A$3003,0)),"—")) | K7: =IF($D7="","",IFERROR(INDEX(ENVIOS!$H$4:$H$3003,MATCH($D7,ENVIOS!$A$4:$A$3003,0)),"—")) | L7: =IF($D7="","",IFERROR(INDEX(ENVIOS!$C$4:$C$3003,MATCH($D7,ENVIOS!$A$4:$A$3003,0)),"")) | M7: Faltante (llegó de menos) | N7: =IF($M7="","",IFERROR(INDEX(CONFIG!$C$4:$C$63,MATCH($M7,CONFIG!$A$4:$A$63,0)),"Media")) | O7: =IF($M7="","",IF($C7="Interna","NO",IFERROR(INDEX(CONFIG!$E$4:$E$63,MATCH($M7,CONFIG!$A$4:$A$63,0)),"NO"))) | P7: Alistamiento (picking) | Q7: Error de alistamiento (picking) | R7: =IF($Q7="","",IFERROR(INDEX(CONFIG!$H$4:$H$63,MATCH($Q7,CONFIG!$G$4:$G$63,0)),"Por definir")) | S7: =IF($Q7="","",IFERROR(INDEX(CONFIG!$I$4:$I$63,MATCH($Q7,CONFIG!$G$4:$G$63,0)),"Por definir")) | T7: 2 | U7: 690000 | V7: Resuelta | W7: Jefe de bodega | X7: =IF(OR($B7="",$M7=""),"",WORKDAY($B7,IFERROR(INDEX(CONFIG!$D$4:$D$63,MATCH($M7,CONFIG!$A$4:$A$63,0)),3))) | Y7: 46258 | Z7: =IF($B7="","",IF($Y7<>"",$Y7-$B7,TODAY()-$B7)) | AA7: =IF($B7="","",IF(IFERROR(INDEX(CONFIG!$L$4:$L$63,MATCH($V7,CONFIG!$K$4:$K$63,0)),"NO")="SÍ",IF(OR($Y7="",$X7=""),"Resuelta",IF($Y7>$X7,"Resuelta tarde","Resuelta a tiempo")),IF($X7="","Sin clasificar",IF(TODAY()>$X7,"Vencida",IF(TODAY()>=$X7-1,"Por vencer","En plazo"))))) | AB7: Reconteo en bodega y despacho del faltante
A8: =IF($B8="","","N-"&TEXT(ROW()-3,"0000")) | B8: 46259 | C8: En ruta | D8: G-2426 | E8: =IF($C8="","",IF($D8="",IF($C8="Interna","Sin guía (interna)","FALTA GUÍA"),IF(COUNTIFS(ENVIOS!$A$4:$A$3003,$D8)=0,"NO EXISTE",IF(COUNTIFS(ENVIOS!$A$4:$A$3003,$D8)>1,"DUPLICADA","OK")))) | F8: =IF($D8="","",IFERROR(INDEX(ENVIOS!$B$4:$B$3003,MATCH($D8,ENVIOS!$A$4:$A$3003,0)),"—")) | G8: =IF($D8="","",IFERROR(INDEX(ENVIOS!$D$4:$D$3003,MATCH($D8,ENVIOS!$A$4:$A$3003,0)),"—")) | H8: =IF($D8="","",IFERROR(INDEX(ENVIOS!$E$4:$E$3003,MATCH($D8,ENVIOS!$A$4:$A$3003,0)),"—")) | I8: =IF($D8="","",IFERROR(INDEX(ENVIOS!$F$4:$F$3003,MATCH($D8,ENVIOS!$A$4:$A$3003,0)),"—")) | J8: =IF($D8="","",IFERROR(INDEX(ENVIOS!$G$4:$G$3003,MATCH($D8,ENVIOS!$A$4:$A$3003,0)),"—")) | K8: =IF($D8="","",IFERROR(INDEX(ENVIOS!$H$4:$H$3003,MATCH($D8,ENVIOS!$A$4:$A$3003,0)),"—")) | L8: =IF($D8="","",IFERROR(INDEX(ENVIOS!$C$4:$C$3003,MATCH($D8,ENVIOS!$A$4:$A$3003,0)),"")) | M8: Faltante (llegó de menos) | N8: =IF($M8="","",IFERROR(INDEX(CONFIG!$C$4:$C$63,MATCH($M8,CONFIG!$A$4:$A$63,0)),"Media")) | O8: =IF($M8="","",IF($C8="Interna","NO",IFERROR(INDEX(CONFIG!$E$4:$E$63,MATCH($M8,CONFIG!$A$4:$A$63,0)),"NO"))) | P8: Alistamiento (picking) | Q8: Inventario descuadrado | R8: =IF($Q8="","",IFERROR(INDEX(CONFIG!$H$4:$H$63,MATCH($Q8,CONFIG!$G$4:$G$63,0)),"Por definir")) | S8: =IF($Q8="","",IFERROR(INDEX(CONFIG!$I$4:$I$63,MATCH($Q8,CONFIG!$G$4:$G$63,0)),"Por definir")) | T8: 2 | U8: 630000 | V8: Resuelta | W8: Jefe de bodega | X8: =IF(OR($B8="",$M8=""),"",WORKDAY($B8,IFERROR(INDEX(CONFIG!$D$4:$D$63,MATCH($M8,CONFIG!$A$4:$A$63,0)),3))) | Y8: 46261 | Z8: =IF($B8="","",IF($Y8<>"",$Y8-$B8,TODAY()-$B8)) | AA8: =IF($B8="","",IF(IFERROR(INDEX(CONFIG!$L$4:$L$63,MATCH($V8,CONFIG!$K$4:$K$63,0)),"NO")="SÍ",IF(OR($Y8="",$X8=""),"Resuelta",IF($Y8>$X8,"Resuelta tarde","Resuelta a tiempo")),IF($X8="","Sin clasificar",IF(TODAY()>$X8,"Vencida",IF(TODAY()>=$X8-1,"Por vencer","En plazo"))))) | AB8: Se despachó el faltante al día siguiente | AC8: Llegó a tiempo pero incompleta: cuenta como entrega a tiempo y NO como OTIF
A9: =IF($B9="","","N-"&TEXT(ROW()-3,"0000")) | B9: 46261 | C9: En ruta | D9: G-2419 | E9: =IF($C9="","",IF($D9="",IF($C9="Interna","Sin guía (interna)","FALTA GUÍA"),IF(COUNTIFS(ENVIOS!$A$4:$A$3003,$D9)=0,"NO EXISTE",IF(COUNTIFS(ENVIOS!$A$4:$A$3003,$D9)>1,"DUPLICADA","OK")))) | F9: =IF($D9="","",IFERROR(INDEX(ENVIOS!$B$4:$B$3003,MATCH($D9,ENVIOS!$A$4:$A$3003,0)),"—")) | G9: =IF($D9="","",IFERROR(INDEX(ENVIOS!$D$4:$D$3003,MATCH($D9,ENVIOS!$A$4:$A$3003,0)),"—")) | H9: =IF($D9="","",IFERROR(INDEX(ENVIOS!$E$4:$E$3003,MATCH($D9,ENVIOS!$A$4:$A$3003,0)),"—")) | I9: =IF($D9="","",IFERROR(INDEX(ENVIOS!$F$4:$F$3003,MATCH($D9,ENVIOS!$A$4:$A$3003,0)),"—")) | J9: =IF($D9="","",IFERROR(INDEX(ENVIOS!$G$4:$G$3003,MATCH($D9,ENVIOS!$A$4:$A$3003,0)),"—")) | K9: =IF($D9="","",IFERROR(INDEX(ENVIOS!$H$4:$H$3003,MATCH($D9,ENVIOS!$A$4:$A$3003,0)),"—")) | L9: =IF($D9="","",IFERROR(INDEX(ENVIOS!$C$4:$C$3003,MATCH($D9,ENVIOS!$A$4:$A$3003,0)),"")) | M9: Cliente ausente / no atiende | N9: =IF($M9="","",IFERROR(INDEX(CONFIG!$C$4:$C$63,MATCH($M9,CONFIG!$A$4:$A$63,0)),"Media")) | O9: =IF($M9="","",IF($C9="Interna","NO",IFERROR(INDEX(CONFIG!$E$4:$E$63,MATCH($M9,CONFIG!$A$4:$A$63,0)),"NO"))) | P9: En ruta / entrega al cliente | Q9: Datos del cliente desactualizados | R9: =IF($Q9="","",IFERROR(INDEX(CONFIG!$H$4:$H$63,MATCH($Q9,CONFIG!$G$4:$G$63,0)),"Por definir")) | S9: =IF($Q9="","",IFERROR(INDEX(CONFIG!$I$4:$I$63,MATCH($Q9,CONFIG!$G$4:$G$63,0)),"Por definir")) | T9: 9 | U9: 2900000 | V9: Resuelta | W9: Servicio al cliente | X9: =IF(OR($B9="",$M9=""),"",WORKDAY($B9,IFERROR(INDEX(CONFIG!$D$4:$D$63,MATCH($M9,CONFIG!$A$4:$A$63,0)),3))) | Y9: 46265 | Z9: =IF($B9="","",IF($Y9<>"",$Y9-$B9,TODAY()-$B9)) | AA9: =IF($B9="","",IF(IFERROR(INDEX(CONFIG!$L$4:$L$63,MATCH($V9,CONFIG!$K$4:$K$63,0)),"NO")="SÍ",IF(OR($Y9="",$X9=""),"Resuelta",IF($Y9>$X9,"Resuelta tarde","Resuelta a tiempo")),IF($X9="","Sin clasificar",IF(TODAY()>$X9,"Vencida",IF(TODAY()>=$X9-1,"Por vencer","En plazo"))))) | AB9: Se actualizó el contacto y se reprogramó
A10: =IF($B10="","","N-"&TEXT(ROW()-3,"0000")) | B10: 46265 | C10: En ruta | D10: G-2420 | E10: =IF($C10="","",IF($D10="",IF($C10="Interna","Sin guía (interna)","FALTA GUÍA"),IF(COUNTIFS(ENVIOS!$A$4:$A$3003,$D10)=0,"NO EXISTE",IF(COUNTIFS(ENVIOS!$A$4:$A$3003,$D10)>1,"DUPLICADA","OK")))) | F10: =IF($D10="","",IFERROR(INDEX(ENVIOS!$B$4:$B$3003,MATCH($D10,ENVIOS!$A$4:$A$3003,0)),"—")) | G10: =IF($D10="","",IFERROR(INDEX(ENVIOS!$D$4:$D$3003,MATCH($D10,ENVIOS!$A$4:$A$3003,0)),"—")) | H10: =IF($D10="","",IFERROR(INDEX(ENVIOS!$E$4:$E$3003,MATCH($D10,ENVIOS!$A$4:$A$3003,0)),"—")) | I10: =IF($D10="","",IFERROR(INDEX(ENVIOS!$F$4:$F$3003,MATCH($D10,ENVIOS!$A$4:$A$3003,0)),"—")) | J10: =IF($D10="","",IFERROR(INDEX(ENVIOS!$G$4:$G$3003,MATCH($D10,ENVIOS!$A$4:$A$3003,0)),"—")) | K10: =IF($D10="","",IFERROR(INDEX(ENVIOS!$H$4:$H$3003,MATCH($D10,ENVIOS!$A$4:$A$3003,0)),"—")) | L10: =IF($D10="","",IFERROR(INDEX(ENVIOS!$C$4:$C$3003,MATCH($D10,ENVIOS!$A$4:$A$3003,0)),"")) | M10: Cliente rechaza el envío | N10: =IF($M10="","",IFERROR(INDEX(CONFIG!$C$4:$C$63,MATCH($M10,CONFIG!$A$4:$A$63,0)),"Media")) | O10: =IF($M10="","",IF($C10="Interna","NO",IFERROR(INDEX(CONFIG!$E$4:$E$63,MATCH($M10,CONFIG!$A$4:$A$63,0)),"NO"))) | P10: En ruta / entrega al cliente | Q10: Cliente sin cupo / cartera bloqueada | R10: =IF($Q10="","",IFERROR(INDEX(CONFIG!$H$4:$H$63,MATCH($Q10,CONFIG!$G$4:$G$63,0)),"Por definir")) | S10: =IF($Q10="","",IFERROR(INDEX(CONFIG!$I$4:$I$63,MATCH($Q10,CONFIG!$G$4:$G$63,0)),"Por definir")) | T10: 12 | U10: 3800000 | V10: Esperando al cliente | W10: Cartera | X10: =IF(OR($B10="",$M10=""),"",WORKDAY($B10,IFERROR(INDEX(CONFIG!$D$4:$D$63,MATCH($M10,CONFIG!$A$4:$A$63,0)),3))) | Z10: =IF($B10="","",IF($Y10<>"",$Y10-$B10,TODAY()-$B10)) | AA10: =IF($B10="","",IF(IFERROR(INDEX(CONFIG!$L$4:$L$63,MATCH($V10,CONFIG!$K$4:$K$63,0)),"NO")="SÍ",IF(OR($Y10="",$X10=""),"Resuelta",IF($Y10>$X10,"Resuelta tarde","Resuelta a tiempo")),IF($X10="","Sin clasificar",IF(TODAY()>$X10,"Vencida",IF(TODAY()>=$X10-1,"Por vencer","En plazo"))))) | AC10: Cartera está revisando el cupo
A11: =IF($B11="","","N-"&TEXT(ROW()-3,"0000")) | B11: 46265 | C11: En ruta | D11: G-2413 | E11: =IF($C11="","",IF($D11="",IF($C11="Interna","Sin guía (interna)","FALTA GUÍA"),IF(COUNTIFS(ENVIOS!$A$4:$A$3003,$D11)=0,"NO EXISTE",IF(COUNTIFS(ENVIOS!$A$4:$A$3003,$D11)>1,"DUPLICADA","OK")))) | F11: =IF($D11="","",IFERROR(INDEX(ENVIOS!$B$4:$B$3003,MATCH($D11,ENVIOS!$A$4:$A$3003,0)),"—")) | G11: =IF($D11="","",IFERROR(INDEX(ENVIOS!$D$4:$D$3003,MATCH($D11,ENVIOS!$A$4:$A$3003,0)),"—")) | H11: =IF($D11="","",IFERROR(INDEX(ENVIOS!$E$4:$E$3003,MATCH($D11,ENVIOS!$A$4:$A$3003,0)),"—")) | I11: =IF($D11="","",IFERROR(INDEX(ENVIOS!$F$4:$F$3003,MATCH($D11,ENVIOS!$A$4:$A$3003,0)),"—")) | J11: =IF($D11="","",IFERROR(INDEX(ENVIOS!$G$4:$G$3003,MATCH($D11,ENVIOS!$A$4:$A$3003,0)),"—")) | K11: =IF($D11="","",IFERROR(INDEX(ENVIOS!$H$4:$H$3003,MATCH($D11,ENVIOS!$A$4:$A$3003,0)),"—")) | L11: =IF($D11="","",IFERROR(INDEX(ENVIOS!$C$4:$C$3003,MATCH($D11,ENVIOS!$A$4:$A$3003,0)),"")) | M11: Producto equivocado | N11: =IF($M11="","",IFERROR(INDEX(CONFIG!$C$4:$C$63,MATCH($M11,CONFIG!$A$4:$A$63,0)),"Media")) | O11: =IF($M11="","",IF($C11="Interna","NO",IFERROR(INDEX(CONFIG!$E$4:$E$63,MATCH($M11,CONFIG!$A$4:$A$63,0)),"NO"))) | P11: Alistamiento (picking) | Q11: Error de alistamiento (picking) | R11: =IF($Q11="","",IFERROR(INDEX(CONFIG!$H$4:$H$63,MATCH($Q11,CONFIG!$G$4:$G$63,0)),"Por definir")) | S11: =IF($Q11="","",IFERROR(INDEX(CONFIG!$I$4:$I$63,MATCH($Q11,CONFIG!$G$4:$G$63,0)),"Por definir")) | T11: 3 | U11: 980000 | V11: Resuelta | W11: Jefe de bodega | X11: =IF(OR($B11="",$M11=""),"",WORKDAY($B11,IFERROR(INDEX(CONFIG!$D$4:$D$63,MATCH($M11,CONFIG!$A$4:$A$63,0)),3))) | Y11: 46268 | Z11: =IF($B11="","",IF($Y11<>"",$Y11-$B11,TODAY()-$B11)) | AA11: =IF($B11="","",IF(IFERROR(INDEX(CONFIG!$L$4:$L$63,MATCH($V11,CONFIG!$K$4:$K$63,0)),"NO")="SÍ",IF(OR($Y11="",$X11=""),"Resuelta",IF($Y11>$X11,"Resuelta tarde","Resuelta a tiempo")),IF($X11="","Sin clasificar",IF(TODAY()>$X11,"Vencida",IF(TODAY()>=$X11-1,"Por vencer","En plazo"))))) | AB11: Se recogió y se despachó la referencia correcta
A12: =IF($B12="","","N-"&TEXT(ROW()-3,"0000")) | B12: 46267 | C12: En ruta | D12: G-2425 | E12: =IF($C12="","",IF($D12="",IF($C12="Interna","Sin guía (interna)","FALTA GUÍA"),IF(COUNTIFS(ENVIOS!$A$4:$A$3003,$D12)=0,"NO EXISTE",IF(COUNTIFS(ENVIOS!$A$4:$A$3003,$D12)>1,"DUPLICADA","OK")))) | F12: =IF($D12="","",IFERROR(INDEX(ENVIOS!$B$4:$B$3003,MATCH($D12,ENVIOS!$A$4:$A$3003,0)),"—")) | G12: =IF($D12="","",IFERROR(INDEX(ENVIOS!$D$4:$D$3003,MATCH($D12,ENVIOS!$A$4:$A$3003,0)),"—")) | H12: =IF($D12="","",IFERROR(INDEX(ENVIOS!$E$4:$E$3003,MATCH($D12,ENVIOS!$A$4:$A$3003,0)),"—")) | I12: =IF($D12="","",IFERROR(INDEX(ENVIOS!$F$4:$F$3003,MATCH($D12,ENVIOS!$A$4:$A$3003,0)),"—")) | J12: =IF($D12="","",IFERROR(INDEX(ENVIOS!$G$4:$G$3003,MATCH($D12,ENVIOS!$A$4:$A$3003,0)),"—")) | K12: =IF($D12="","",IFERROR(INDEX(ENVIOS!$H$4:$H$3003,MATCH($D12,ENVIOS!$A$4:$A$3003,0)),"—")) | L12: =IF($D12="","",IFERROR(INDEX(ENVIOS!$C$4:$C$3003,MATCH($D12,ENVIOS!$A$4:$A$3003,0)),"")) | M12: Soporte de entrega sin firmar | N12: =IF($M12="","",IFERROR(INDEX(CONFIG!$C$4:$C$63,MATCH($M12,CONFIG!$A$4:$A$63,0)),"Media")) | O12: =IF($M12="","",IF($C12="Interna","NO",IFERROR(INDEX(CONFIG!$E$4:$E$63,MATCH($M12,CONFIG!$A$4:$A$63,0)),"NO"))) | P12: En ruta / entrega al cliente | Q12: Conductor sin capacitación o procedimiento | R12: =IF($Q12="","",IFERROR(INDEX(CONFIG!$H$4:$H$63,MATCH($Q12,CONFIG!$G$4:$G$63,0)),"Por definir")) | S12: =IF($Q12="","",IFERROR(INDEX(CONFIG!$I$4:$I$63,MATCH($Q12,CONFIG!$G$4:$G$63,0)),"Por definir")) | T12: 0 | U12: 0 | V12: En gestión | W12: Analista de transporte | X12: =IF(OR($B12="",$M12=""),"",WORKDAY($B12,IFERROR(INDEX(CONFIG!$D$4:$D$63,MATCH($M12,CONFIG!$A$4:$A$63,0)),3))) | Z12: =IF($B12="","",IF($Y12<>"",$Y12-$B12,TODAY()-$B12)) | AA12: =IF($B12="","",IF(IFERROR(INDEX(CONFIG!$L$4:$L$63,MATCH($V12,CONFIG!$K$4:$K$63,0)),"NO")="SÍ",IF(OR($Y12="",$X12=""),"Resuelta",IF($Y12>$X12,"Resuelta tarde","Resuelta a tiempo")),IF($X12="","Sin clasificar",IF(TODAY()>$X12,"Vencida",IF(TODAY()>=$X12-1,"Por vencer","En plazo"))))) | AC12: Falta el sello del cliente
