Workbook
Name TIPOS_NOVEDAD: OFFSET(LISTAS!$A$3,0,0,MAX(1,COUNTA(LISTAS!$A$3:$A$42)),1)
Name CAUSAS_RAIZ: OFFSET(LISTAS!$E$3,0,0,MAX(1,COUNTA(LISTAS!$E$3:$E$42)),1)
Name ESTADOS_NOV: OFFSET(LISTAS!$H$3,0,0,MAX(1,COUNTA(LISTAS!$H$3:$H$42)),1)
Name TRANSPORTADORAS: OFFSET(LISTAS!$K$3,0,0,MAX(1,COUNTA(LISTAS!$K$3:$K$42)),1)
Name RESPONSABLES: OFFSET(LISTAS!$M$3,0,0,MAX(1,COUNTA(LISTAS!$M$3:$M$42)),1)

Sheet GUÍA
B2: GUÍA DE USO — MATRIZ DE NOVEDADES DE LOGÍSTICA Y TRANSPORTE · GESTOAGRO S.A.S.
B3: LA REGLA DE ORO — COLORES
B4: • Celdas AMARILLAS = usted las digita. • Celdas GRISES = se calculan solas, NO las toque. • Encabezado DORADO = columna de captura. • Encabezado AZUL = columna calculada.
B5: FLUJO DIARIO — PASO A PASO
B6: 1) DESPACHOS: pegue el export de Access desde la fila 3 (columnas A a J, mismo orden). Luego complete a mano Destino/Ciudad (K), Cajas enviadas (L) y Valor despachado (M).
B7: 2) NOVEDADES: para registrar un evento digite SOLO la Fecha novedad (B) y el # Pedido / Remisión (C). Cliente, destino, ruta, transportadora, transportador, placa y fecha de despacho se traen solos desde DESPACHOS.
B8: 3) Elija de las listas: Tipo de novedad (L), Causa raíz (M), Responsable (O) y Estado (T). El Área responsable, la Criticidad y la Fecha compromiso se calculan solas.
B9: 4) Registre el impacto: Cajas afectadas (Q) y Valor afectado (R). El % del despacho sale solo.
B10: 5) Al resolver el caso: cambie el Estado (T) a uno que cierre y escriba la Fecha cierre real (V). El semáforo pasa a CERRADA EN SLA o CERRADA FUERA DE SLA.
B11: CÓMO LEER EL SEMÁFORO SLA (columna Y)
B12: EN PLAZO = dentro de la fecha compromiso. POR VENCER = vence hoy o mañana. VENCIDA = ya pasó la fecha compromiso y sigue abierta. CERRADA EN SLA = se resolvió a tiempo. CERRADA FUERA DE SLA = se resolvió tarde. SIN CLASIFICAR = falta el Tipo de novedad.
B13: VERIFICACIÓN DE LA LLAVE (columna K)
... B24: Las fórmulas funcionan igual salvo dos: BUSCARX no existe (use ÍNDICE+COINCIDIR, que es lo que trae este archivo) y los nombres definidos no aceptan DESPLAZAMIENTO. En Sheets apunte la validación de datos directamente al rango, por ejemplo LISTAS!A3:A42.

Sheet DASHBOARD
B2: DASHBOARD DE NOVEDADES DE LOGÍSTICA Y TRANSPORTE — GESTOAGRO S.A.S.
B3: Todos los indicadores respetan el PERIODO de abajo. Novedades se filtran por Fecha novedad; despachos por Fecha despacho.
B4: 📅 PERIODO A CONSULTAR | D4: Desde: | E4: 46023 | F4: Hasta: | G4: 46387 | H4: ◄ Cambie las dos fechas AMARILLAS y todo el tablero se recalcula.
B6: NOVEDADES DEL PERIODO | D6: PEDIDOS DESPACHADOS | F6: % RATIO DE INCIDENCIA | H6: NOVEDADES ABIERTAS | J6: NOVEDADES CERRADAS
B7: =COUNTIFS(NOVEDADES!$B$4:$B$2003,">="&$E$4,NOVEDADES!$B$4:$B$2003,"<="&$G$4) | D7: =COUNTIFS(DESPACHOS!$J$3:$J$3002,">="&$E$4,DESPACHOS!$J$3:$J$3002,"<="&$G$4) | F7: =IFERROR(COUNTIFS(DESPACHOS!$J$3:$J$3002,">="&$E$4,DESPACHOS!$J$3:$J$3002,"<="&$G$4,DESPACHOS!$O$3:$O$3002,"SÍ*")/COUNTIFS(DESPACHOS!$J$3:$J$3002,">="&$E$4,DESPACHOS!$J$3:$J$3002,"<="&$G$4),0) | H7: =COUNTIFS(NOVEDADES!$Y$4:$Y$2003,"EN PLAZO",NOVEDADES!$B$4:$B$2003,">="&$E$4,NOVEDADES!$B$4:$B$2003,"<="&$G$4)+COUNTIFS(NOVEDADES!$Y$4:$Y$2003,"POR VENCER",NOVEDADES!$B$4:$B$2003,">="&$E$4,NOVEDADES!$B$4:$B$2003,"<="&$G$4)+COUNTIFS(NOVEDADES!$Y$4:$Y$2003,"VENCIDA",NOVEDADES!$B$4:$B$2003,">="&$E$4,NOVEDADES!$B$4:$B$2003,"<="&$G$4)+COUNTIFS(NOVEDADES!$Y$4:$Y$2003,"SIN CLASIFICAR",NOVEDADES!$B$4:$B$2003,">="&$E$4,NOVEDADES!$B$4:$B$2003,"<="&$G$4) | J7: =COUNTIFS(NOVEDADES!$Y$4:$Y$2003,"CERRADA*",NOVEDADES!$B$4:$B$2003,">="&$E$4,NOVEDADES!$B$4:$B$2003,"<="&$G$4)
B9: VALOR IMPACTADO | D9: CAJAS AFECTADAS | F9: DÍAS PROM. DE GESTIÓN | H9: VENCIDAS (SLA roto) | J9: % CUMPLIMIENTO SLA
B10: =SUMIFS(NOVEDADES!$R$4:$R$2003,NOVEDADES!$B$4:$B$2003,">="&$E$4,NOVEDADES!$B$4:$B$2003,"<="&$G$4) | D10: =SUMIFS(NOVEDADES!$Q$4:$Q$2003,NOVEDADES!$B$4:$B$2003,">="&$E$4,NOVEDADES!$B$4:$B$2003,"<="&$G$4) | F10: =IFERROR(ROUND(AVERAGEIFS(NOVEDADES!$W$4:$W$2003,NOVEDADES!$B$4:$B$2003,">="&$E$4,NOVEDADES!$B$4:$B$2003,"<="&$G$4),1),0) | H10: =COUNTIFS(NOVEDADES!$Y$4:$Y$2003,"VENCIDA",NOVEDADES!$B$4:$B$2003,">="&$E$4,NOVEDADES!$B$4:$B$2003,"<="&$G$4) | J10: =IFERROR(COUNTIFS(NOVEDADES!$Y$4:$Y$2003,"CERRADA EN SLA",NOVEDADES!$B$4:$B$2003,">="&$E$4,NOVEDADES!$B$4:$B$2003,"<="&$G$4)/COUNTIFS(NOVEDADES!$Y$4:$Y$2003,"CERRADA*",NOVEDADES!$B$4:$B$2003,">="&$E$4,NOVEDADES!$B$4:$B$2003,"<="&$G$4),"—")
B12: 1. CAUSA RAÍZ — CONTEO, PARTICIPACIÓN E IMPACTO ECONÓMICO | N12: CONSULTA RÁPIDA DE PEDIDO
B13: Causa raíz | C13: # Novedades | D13: % Participación | E13: Valor impactado | F13: Orden (auxiliar) | N13: Digite # Pedido →
B14: =IF(LISTAS!$E3="","",LISTAS!$E3) | C14: =IF($B14="","",COUNTIFS(NOVEDADES!$M$4:$M$2003,$B14,NOVEDADES!$B$4:$B$2003,">="&$E$4,NOVEDADES!$B$4:$B$2003,"<="&$G$4)) | D14: =IF($B14="","",IFERROR($C14/$C$31,0)) | E14: =IF($B14="","",SUMIFS(NOVEDADES!$R$4:$R$2003,NOVEDADES!$M$4:$M$2003,$B14,NOVEDADES!$B$4:$B$2003,">="&$E$4,NOVEDADES!$B$4:$B$2003,"<="&$G$4)) | F14: =IF($B14="","",$C14+ROW()/100000) | N14: Cliente | O14: =IF($O$13="","—",IFERROR(INDEX(DESPACHOS!$D$3:$D$3002,MATCH($O$13,DESPACHOS!$B$3:$B$3002,0)),"NO EXISTE"))
B15: =IF(LISTAS!$E4="","",LISTAS!$E4) | C15: =IF($B15="","",COUNTIFS(NOVEDADES!$M$4:$M$2003,$B15,NOVEDADES!$B$4:$B$2003,">="&$E$4,NOVEDADES!$B$4:$B$2003,"<="&$G$4)) | D15: =IF($B15="","",IFERROR($C15/$C$31,0)) | E15: =IF($B15="","",SUMIFS(NOVEDADES!$R$4:$R$2003,NOVEDADES!$M$4:$M$2003,$B15,NOVEDADES!$B$4:$B$2003,">="&$E$4,NOVEDADES!$B$4:$B$2003,"<="&$G$4)) | F15: =IF($B15="","",$C15+ROW()/100000) | N15: # Factura | O15: =IF($O$13="","—",IFERROR(INDEX(DESPACHOS!$C$3:$C$3002,MATCH($O$13,DESPACHOS!$B$3:$B$3002,0)),"—"))
B16: =IF(LISTAS!$E5="","",LISTAS!$E5) | C16: =IF($B16="","",COUNTIFS(NOVEDADES!$M$4:$M$2003,$B16,NOVEDADES!$B$4:$B$2003,">="&$E$4,NOVEDADES!$B$4:$B$2003,"<="&$G$4)) | D16: =IF($B16="","",IFERROR($C16/$C$31,0)) | E16: =IF($B16="","",SUMIFS(NOVEDADES!$R$4:$R$2003,NOVEDADES!$M$4:$M$2003,$B16,NOVEDADES!$B$4:$B$2003,">="&$E$4,NOVEDADES!$B$4:$B$2003,"<="&$G$4)) | F16: =IF($B16="","",$C16+ROW()/100000) | N16: Destino / Ciudad | O16: =IF($O$13="","—",IFERROR(INDEX(DESPACHOS!$K$3:$K$3002,MATCH($O$13,DESPACHOS!$B$3:$B$3002,0)),"—"))
B17: =IF(LISTAS!$E6="","",LISTAS!$E6) | C17: =IF($B17="","",COUNTIFS(NOVEDADES!$M$4:$M$2003,$B17,NOVEDADES!$B$4:$B$2003,">="&$E$4,NOVEDADES!$B$4:$B$2003,"<="&$G$4)) | D17: =IF($B17="","",IFERROR($C17/$C$31,0)) | E17: =IF($B17="","",SUMIFS(NOVEDADES!$R$4:$R$2003,NOVEDADES!$M$4:$M$2003,$B17,NOVEDADES!$B$4:$B$2003,">="&$E$4,NOVEDADES!$B$4:$B$2003,"<="&$G$4)) | F17: =IF($B17="","",$C17+ROW()/100000) | N17: Transportadora | O17: =IF($O$13="","—",IFERROR(INDEX(DESPACHOS!$F$3:$F$3002,MATCH($O$13,DESPACHOS!$B$3:$B$3002,0)),"—"))
B18: =IF(LISTAS!$E7="","",LISTAS!$E7) | C18: =IF($B18="","",COUNTIFS(NOVEDADES!$M$4:$M$2003,$B18,NOVEDADES!$B$4:$B$2003,">="&$E$4,NOVEDADES!$B$4:$B$2003,"<="&$G$4)) | D18: =IF($B18="","",IFERROR($C18/$C$31,0)) | E18: =IF($B18="","",SUMIFS(NOVEDADES!$R$4:$R$2003,NOVEDADES!$M$4:$M$2003,$B18,NOVEDADES!$B$4:$B$2003,">="&$E$4,NOVEDADES!$B$4:$B$2003,"<="&$G$4)) | F18: =IF($B18="","",$C18+ROW()/100000) | N18: Placa | O18: =IF($O$13="","—",IFERROR(INDEX(DESPACHOS!$H$3:$H$3002,MATCH($O$13,DESPACHOS!$B$3:$B$3002,0)),"—"))
B19: =IF(LISTAS!$E8="","",LISTAS!$E8) | C19: =IF($B19="","",COUNTIFS(NOVEDADES!$M$4:$M$2003,$B19,NOVEDADES!$B$4:$B$2003,">="&$E$4,NOVEDADES!$B$4:$B$2003,"<="&$G$4)) | D19: =IF($B19="","",IFERROR($C19/$C$31,0)) | E19: =IF($B19="","",SUMIFS(NOVEDADES!$R$4:$R$2003,NOVEDADES!$M$4:$M$2003,$B19,NOVEDADES!$B$4:$B$2003,">="&$E$4,NOVEDADES!$B$4:$B$2003,"<="&$G$4)) | F19: =IF($B19="","",$C19+ROW()/100000) | N19: Fecha despacho | O19: =IF($O$13="","—",IFERROR(INDEX(DESPACHOS!$J$3:$J$3002,MATCH($O$13,DESPACHOS!$B$3:$B$3002,0)),"—"))
B20: =IF(LISTAS!$E9="","",LISTAS!$E9) | C20: =IF($B20="","",COUNTIFS(NOVEDADES!$M$4:$M$2003,$B20,NOVEDADES!$B$4:$B$2003,">="&$E$4,NOVEDADES!$B$4:$B$2003,"<="&$G$4)) | D20: =IF($B20="","",IFERROR($C20/$C$31,0)) | E20: =IF($B20="","",SUMIFS(NOVEDADES!$R$4:$R$2003,NOVEDADES!$M$4:$M$2003,$B20,NOVEDADES!$B$4:$B$2003,">="&$E$4,NOVEDADES!$B$4:$B$2003,"<="&$G$4)) | F20: =IF($B20="","",$C20+ROW()/100000) | N20: Novedades del pedido | O20: =IF($O$13="","—",COUNTIFS(NOVEDADES!$C$4:$C$2003,$O$13))
B21: =IF(LISTAS!$E10="","",LISTAS!$E10) | C21: =IF($B21="","",COUNTIFS(NOVEDADES!$M$4:$M$2003,$B21,NOVEDADES!$B$4:$B$2003,">="&$E$4,NOVEDADES!$B$4:$B$2003,"<="&$G$4)) | D21: =IF($B21="","",IFERROR($C21/$C$31,0)) | E21: =IF($B21="","",SUMIFS(NOVEDADES!$R$4:$R$2003,NOVEDADES!$M$4:$M$2003,$B21,NOVEDADES!$B$4:$B$2003,">="&$E$4,NOVEDADES!$B$4:$B$2003,"<="&$G$4)) | F21: =IF($B21="","",$C21+ROW()/100000) | N21: Valor afectado | O21: =IF($O$13="","—",SUMIFS(NOVEDADES!$R$4:$R$2003,NOVEDADES!$C$4:$C$2003,$O$13))
B22: =IF(LISTAS!$E11="","",LISTAS!$E11) | C22: =IF($B22="","",COUNTIFS(NOVEDADES!$M$4:$M$2003,$B22,NOVEDADES!$B$4:$B$2003,">="&$E$4,NOVEDADES!$B$4:$B$2003,"<="&$G$4)) | D22: =IF($B22="","",IFERROR($C22/$C$31,0)) | E22: =IF($B22="","",SUMIFS(NOVEDADES!$R$4:$R$2003,NOVEDADES!$M$4:$M$2003,$B22,NOVEDADES!$B$4:$B$2003,">="&$E$4,NOVEDADES!$B$4:$B$2003,"<="&$G$4)) | F22: =IF($B22="","",$C22+ROW()/100000) | N22: Estado más reciente | O22: =IF($O$13="","—",IFERROR(LOOKUP(2,1/(NOVEDADES!$C$4:$C$2003=$O$13),NOVEDADES!$T$4:$T$2003),"—"))
B23: =IF(LISTAS!$E12="","",LISTAS!$E12) | C23: =IF($B23="","",COUNTIFS(NOVEDADES!$M$4:$M$2003,$B23,NOVEDADES!$B$4:$B$2003,">="&$E$4,NOVEDADES!$B$4:$B$2003,"<="&$G$4)) | D23: =IF($B23="","",IFERROR($C23/$C$31,0)) | E23: =IF($B23="","",SUMIFS(NOVEDADES!$R$4:$R$2003,NOVEDADES!$M$4:$M$2003,$B23,NOVEDADES!$B$4:$B$2003,">="&$E$4,NOVEDADES!$B$4:$B$2003,"<="&$G$4)) | F23: =IF($B23="","",$C23+ROW()/100000) | N23: Semáforo SLA | O23: =IF($O$13="","—",IFERROR(LOOKUP(2,1/(NOVEDADES!$C$4:$C$2003=$O$13),NOVEDADES!$Y$4:$Y$2003),"—"))
B24: =IF(LISTAS!$E13="","",LISTAS!$E13) | C24: =IF($B24="","",COUNTIFS(NOVEDADES!$M$4:$M$2003,$B24,NOVEDADES!$B$4:$B$2003,">="&$E$4,NOVEDADES!$B$4:$B$2003,"<="&$G$4)) | D24: =IF($B24="","",IFERROR($C24/$C$31,0)) | E24: =IF($B24="","",SUMIFS(NOVEDADES!$R$4:$R$2003,NOVEDADES!$M$4:$M$2003,$B24,NOVEDADES!$B$4:$B$2003,">="&$E$4,NOVEDADES!$B$4:$B$2003,"<="&$G$4)) | F24: =IF($B24="","",$C24+ROW()/100000)
B25: =IF(LISTAS!$E14="","",LISTAS!$E14) | C25: =IF($B25="","",COUNTIFS(NOVEDADES!$M$4:$M$2003,$B25,NOVEDADES!$B$4:$B$2003,">="&$E$4,NOVEDADES!$B$4:$B$2003,"<="&$G$4)) | D25: =IF($B25="","",IFERROR($C25/$C$31,0)) | E25: =IF($B25="","",SUMIFS(NOVEDADES!$R$4:$R$2003,NOVEDADES!$M$4:$M$2003,$B25,NOVEDADES!$B$4:$B$2003,">="&$E$4,NOVEDADES!$B$4:$B$2003,"<="&$G$4)) | F25: =IF($B25="","",$C25+ROW()/100000) | N25: El semáforo y el estado corresponden a la novedad más reciente registrada para ese pedido.
B26: =IF(LISTAS!$E15="","",LISTAS!$E15) | C26: =IF($B26="","",COUNTIFS(NOVEDADES!$M$4:$M$2003,$B26,NOVEDADES!$B$4:$B$2003,">="&$E$4,NOVEDADES!$B$4:$B$2003,"<="&$G$4)) | D26: =IF($B26="","",IFERROR($C26/$C$31,0)) | E26: =IF($B26="","",SUMIFS(NOVEDADES!$R$4:$R$2003,NOVEDADES!$M$4:$M$2003,$B26,NOVEDADES!$B$4:$B$2003,">="&$E$4,NOVEDADES!$B$4:$B$2003,"<="&$G$4)) | F26: =IF($B26="","",$C26+ROW()/100000)
B27: =IF(LISTAS!$E16="","",LISTAS!$E16) | C27: =IF($B27="","",COUNTIFS(NOVEDADES!$M$4:$M$2003,$B27,NOVEDADES!$B$4:$B$2003,">="&$E$4,NOVEDADES!$B$4:$B$2003,"<="&$G$4)) | D27: =IF($B27="","",IFERROR($C27/$C$31,0)) | E27: =IF($B27="","",SUMIFS(NOVEDADES!$R$4:$R$2003,NOVEDADES!$M$4:$M$2003,$B27,NOVEDADES!$B$4:$B$2003,">="&$E$4,NOVEDADES!$B$4:$B$2003,"<="&$G$4)) | F27: =IF($B27="","",$C27+ROW()/100000)
B28: =IF(LISTAS!$E17="","",LISTAS!$E17) | C28: =IF($B28="","",COUNTIFS(NOVEDADES!$M$4:$M$2003,$B28,NOVEDADES!$B$4:$B$2003,">="&$E$4,NOVEDADES!$B$4:$B$2003,"<="&$G$4)) | D28: =IF($B28="","",IFERROR($C28/$C$31,0)) | E28: =IF($B28="","",SUMIFS(NOVEDADES!$R$4:$R$2003,NOVEDADES!$M$4:$M$2003,$B28,NOVEDADES!$B$4:$B$2003,">="&$E$4,NOVEDADES!$B$4:$B$2003,"<="&$G$4)) | F28: =IF($B28="","",$C28+ROW()/100000)
B29: =IF(LISTAS!$E18="","",LISTAS!$E18) | C29: =IF($B29="","",COUNTIFS(NOVEDADES!$M$4:$M$2003,$B29,NOVEDADES!$B$4:$B$2003,">="&$E$4,NOVEDADES!$B$4:$B$2003,"<="&$G$4)) | D29: =IF($B29="","",IFERROR($C29/$C$31,0)) | E29: =IF($B29="","",SUMIFS(NOVEDADES!$R$4:$R$2003,NOVEDADES!$M$4:$M$2003,$B29,NOVEDADES!$B$4:$B$2003,">="&$E$4,NOVEDADES!$B$4:$B$2003,"<="&$G$4)) | F29: =IF($B29="","",$C29+ROW()/100000)
B30: =IF(LISTAS!$E19="","",LISTAS!$E19) | C30: =IF($B30="","",COUNTIFS(NOVEDADES!$M$4:$M$2003,$B30,NOVEDADES!$B$4:$B$2003,">="&$E$4,NOVEDADES!$B$4:$B$2003,"<="&$G$4)) | D30: =IF($B30="","",IFERROR($C30/$C$31,0)) | E30: =IF($B30="","",SUMIFS(NOVEDADES!$R$4:$R$2003,NOVEDADES!$M$4:$M$2003,$B30,NOVEDADES!$B$4:$B$2003,">="&$E$4,NOVEDADES!$B$4:$B$2003,"<="&$G$4)) | F30: =IF($B30="","",$C30+ROW()/100000)
B31: TOTAL | C31: =SUM($C$14:$C$30) | D31: =IF($C$31=0,0,1) | E31: =SUM($E$14:$E$30)
B33: 2. TOP 5 CAUSAS RAÍZ — ranking automático del periodo
B34: Puesto | C34: Causa raíz | D34: # Novedades | E34: % Participación
B35: ="#"&1 | C35: =IFERROR(INDEX($B$14:$B$30,MATCH(LARGE($F$14:$F$30,1),$F$14:$F$30,0)),"—") | D35: =IFERROR(INDEX($C$14:$C$30,MATCH(LARGE($F$14:$F$30,1),$F$14:$F$30,0)),0) | E35: =IFERROR($D35/$C$31,0)
B36: ="#"&2 | C36: =IFERROR(INDEX($B$14:$B$30,MATCH(LARGE($F$14:$F$30,2),$F$14:$F$30,0)),"—") | D36: =IFERROR(INDEX($C$14:$C$30,MATCH(LARGE($F$14:$F$30,2),$F$14:$F$30,0)),0) | E36: =IFERROR($D36/$C$31,0)
B37: ="#"&3 | C37: =IFERROR(INDEX($B$14:$B$30,MATCH(LARGE($F$14:$F$30,3),$F$14:$F$30,0)),"—") | D37: =IFERROR(INDEX($C$14:$C$30,MATCH(LARGE($F$14:$F$30,3),$F$14:$F$30,0)),0) | E37: =IFERROR($D37/$C$31,0)
B38: ="#"&4 | C38: =IFERROR(INDEX($B$14:$B$30,MATCH(LARGE($F$14:$F$30,4),$F$14:$F$30,0)),"—") | D38: =IFERROR(INDEX($C$14:$C$30,MATCH(LARGE($F$14:$F$30,4),$F$14:$F$30,0)),0) | E38: =IFERROR($D38/$C$31,0)
B39: ="#"&5 | C39: =IFERROR(INDEX($B$14:$B$30,MATCH(LARGE($F$14:$F$30,5),$F$14:$F$30,0)),"—") | D39: =IFERROR(INDEX($C$14:$C$30,MATCH(LARGE($F$14:$F$30,5),$F$14:$F$30,0)),0) | E39: =IFERROR($D39/$C$31,0)
B41: 3. NOVEDADES POR TIPO — volumen, impacto y estado de gestión
B42: Tipo de novedad | C42: # Novedades | D42: % Part. | E42: Valor impactado | F42: Abiertas | G42: Cerradas | H42: Vencidas
B43: =IF(LISTAS!$A3="","",LISTAS!$A3) | C43: =IF($B43="","",COUNTIFS(NOVEDADES!$L$4:$L$2003,$B43,NOVEDADES!$B$4:$B$2003,">="&$E$4,NOVEDADES!$B$4:$B$2003,"<="&$G$4)) | D43: =IF($B43="","",IFERROR($C43/$C$59,0)) | E43: =IF($B43="","",SUMIFS(NOVEDADES!$R$4:$R$2003,NOVEDADES!$L$4:$L$2003,$B43,NOVEDADES!$B$4:$B$2003,">="&$E$4,NOVEDADES!$B$4:$B$2003,"<="&$G$4)) | F43: =IF($B43="","",COUNTIFS(NOVEDADES!$Y$4:$Y$2003,"EN PLAZO",NOVEDADES!$B$4:$B$2003,">="&$E$4,NOVEDADES!$B$4:$B$2003,"<="&$G$4,NOVEDADES!$L$4:$L$2003,$B43)+COUNTIFS(NOVEDADES!$Y$4:$Y$2003,"POR VENCER",NOVEDADES!$B$4:$B$2003,">="&$E$4,NOVEDADES!$B$4:$B$2003,"<="&$G$4,NOVEDADES!$L$4:$L$2003,$B43)+COUNTIFS(NOVEDADES!$Y$4:$Y$2003,"VENCIDA",NOVEDADES!$B$4:$B$2003,">="&$E$4,NOVEDADES!$B$4:$B$2003,"<="&$G$4,NOVEDADES!$L$4:$L$2003,$B43)+COUNTIFS(NOVEDADES!$Y$4:$Y$2003,"SIN CLASIFICAR",NOVEDADES!$B$4:$B$2003,">="&$E$4,NOVEDADES!$B$4:$B$2003,"<="&$G$4,NOVEDADES!$L$4:$L$2003,$B43)) | G43: =IF($B43="","",COUNTIFS(NOVEDADES!$L$4:$L$2003,$B43,NOVEDADES!$Y$4:$Y$2003,"CERRADA*",NOVEDADES!$B$4:$B$2003,">="&$E$4,NOVEDADES!$B$4:$B$2003,"<="&$G$4)) | H43: =IF($B43="","",COUNTIFS(NOVEDADES!$L$4:$L$2003,$B43,NOVEDADES!$Y$4:$Y$2003,"VENCIDA",NOVEDADES!$B$4:$B$2003,">="&$E$4,NOVEDADES!$B$4:$B$2003,"<="&$G$4))
B44: =IF(LISTAS!$A4="","",LISTAS!$A4) | C44: =IF($B44="","",COUNTIFS(NOVEDADES!$L$4:$L$2003,$B44,NOVEDADES!$B$4:$B$2003,">="&$E$4,NOVEDADES!$B$4:$B$2003,"<="&$G$4)) | D44: =IF($B44="","",IFERROR($C44/$C$59,0)) | E44: =IF($B44="","",SUMIFS(NOVEDADES!$R$4:$R$2003,NOVEDADES!$L$4:$L$2003,$B44,NOVEDADES!$B$4:$B$2003,">="&$E$4,NOVEDADES!$B$4:$B$2003,"<="&$G$4)) | F44: =IF($B44="","",COUNTIFS(NOVEDADES!$Y$4:$Y$2003,"EN PLAZO",NOVEDADES!$B$4:$B$2003,">="&$E$4,NOVEDADES!$B$4:$B$2003,"<="&$G$4,NOVEDADES!$L$4:$L$2003,$B44)+COUNTIFS(NOVEDADES!$Y$4:$Y$2003,"POR VENCER",NOVEDADES!$B$4:$B$2003,">="&$E$4,NOVEDADES!$B$4:$B$2003,"<="&$G$4,NOVEDADES!$L$4:$L$2003,$B44)+COUNTIFS(NOVEDADES!$Y$4:$Y$2003,"VENCIDA",NOVEDADES!$B$4:$B$2003,">="&$E$4,NOVEDADES!$B$4:$B$2003,"<="&$G$4,NOVEDADES!$L$4:$L$2003,$B44)+COUNTIFS(NOVEDADES!$Y$4:$Y$2003,"SIN CLASIFICAR",NOVEDADES!$B$4:$B$2003,">="&$E$4,NOVEDADES!$B$4:$B$2003,"<="&$G$4,NOVEDADES!$L$4:$L$2003,$B44)) | G44: =IF($B44="","",COUNTIFS(NOVEDADES!$L$4:$L$2003,$B44,NOVEDADES!$Y$4:$Y$2003,"CERRADA*",NOVEDADES!$B$4:$B$2003,">="&$E$4,NOVEDADES!$B$4:$B$2003,"<="&$G$4)) | H44: =IF($B44="","",COUNTIFS(NOVEDADES!$L$4:$L$2003,$B44,NOVEDADES!$Y$4:$Y$2003,"VENCIDA",NOVEDADES!$B$4:$B$2003,">="&$E$4,NOVEDADES!$B$4:$B$2003,"<="&$G$4))
B45: =IF(LISTAS!$A5="","",LISTAS!$A5) | C45: =IF($B45="","",COUNTIFS(NOVEDADES!$L$4:$L$2003,$B45,NOVEDADES!$B$4:$B$2003,">="&$E$4,NOVEDADES!$B$4:$B$2003,"<="&$G$4)) | D45: =IF($B45="","",IFERROR($C45/$C$59,0)) | E45: =IF($B45="","",SUMIFS(NOVEDADES!$R$4:$R$2003,NOVEDADES!$L$4:$L$2003,$B45,NOVEDADES!$B$4:$B$2003,">="&$E$4,NOVEDADES!$B$4:$B$2003,"<="&$G$4)) | F45: =IF($B45="","",COUNTIFS(NOVEDADES!$Y$4:$Y$2003,"EN PLAZO",NOVEDADES!$B$4:$B$2003,">="&$E$4,NOVEDADES!$B$4:$B$2003,"<="&$G$4,NOVEDADES!$L$4:$L$2003,$B45)+COUNTIFS(NOVEDADES!$Y$4:$Y$2003,"POR VENCER",NOVEDADES!$B$4:$B$2003,">="&$E$4,NOVEDADES!$B$4:$B$2003,"<="&$G$4,NOVEDADES!$L$4:$L$2003,$B45)+COUNTIFS(NOVEDADES!$Y$4:$Y$2003,"VENCIDA",NOVEDADES!$B$4:$B$2003,">="&$E$4,NOVEDADES!$B$4:$B$2003,"<="&$G$4,NOVEDADES!$L$4:$L$2003,$B45)+COUNTIFS(NOVEDADES!$Y$4:$Y$2003,"SIN CLASIFICAR",NOVEDADES!$B$4:$B$2003,">="&$E$4,NOVEDADES!$B$4:$B$2003,"<="&$G$4,NOVEDADES!$L$4:$L$2003,$B45)) | G45: =IF($B45="","",COUNTIFS(NOVEDADES!$L$4:$L$2003,$B45,NOVEDADES!$Y$4:$Y$2003,"CERRADA*",NOVEDADES!$B$4:$B$2003,">="&$E$4,NOVEDADES!$B$4:$B$2003,"<="&$G$4)) | H45: =IF($B45="","",COUNTIFS(NOVEDADES!$L$4:$L$2003,$B45,NOVEDADES!$Y$4:$Y$2003,"VENCIDA",NOVEDADES!$B$4:$B$2003,">="&$E$4,NOVEDADES!$B$4:$B$2003,"<="&$G$4))
B46: =IF(LISTAS!$A6="","",LISTAS!$A6) | C46: =IF($B46="","",COUNTIFS(NOVEDADES!$L$4:$L$2003,$B46,NOVEDADES!$B$4:$B$2003,">="&$E$4,NOVEDADES!$B$4:$B$2003,"<="&$G$4)) | D46: =IF($B46="","",IFERROR($C46/$C$59,0)) | E46: =IF($B46="","",SUMIFS(NOVEDADES!$R$4:$R$2003,NOVEDADES!$L$4:$L$2003,$B46,NOVEDADES!$B$4:$B$2003,">="&$E$4,NOVEDADES!$B$4:$B$2003,"<="&$G$4)) | F46: =IF($B46="","",COUNTIFS(NOVEDADES!$Y$4:$Y$2003,"EN PLAZO",NOVEDADES!$B$4:$B$2003,">="&$E$4,NOVEDADES!$B$4:$B$2003,"<="&$G$4,NOVEDADES!$L$4:$L$2003,$B46)+COUNTIFS(NOVEDADES!$Y$4:$Y$2003,"POR VENCER",NOVEDADES!$B$4:$B$2003,">="&$E$4,NOVEDADES!$B$4:$B$2003,"<="&$G$4,NOVEDADES!$L$4:$L$2003,$B46)+COUNTIFS(NOVEDADES!$Y$4:$Y$2003,"VENCIDA",NOVEDADES!$B$4:$B$2003,">="&$E$4,NOVEDADES!$B$4:$B$2003,"<="&$G$4,NOVEDADES!$L$4:$L$2003,$B46)+COUNTIFS(NOVEDADES!$Y$4:$Y$2003,"SIN CLASIFICAR",NOVEDADES!$B$4:$B$2003,">="&$E$4,NOVEDADES!$B$4:$B$2003,"<="&$G$4,NOVEDADES!$L$4:$L$2003,$B46)) | G46: =IF($B46="","",COUNTIFS(NOVEDADES!$L$4:$L$2003,$B46,NOVEDADES!$Y$4:$Y$2003,"CERRADA*",NOVEDADES!$B$4:$B$2003,">="&$E$4,NOVEDADES!$B$4:$B$2003,"<="&$G$4)) | H46: =IF($B46="","",COUNTIFS(NOVEDADES!$L$4:$L$2003,$B46,NOVEDADES!$Y$4:$Y$2003,"VENCIDA",NOVEDADES!$B$4:$B$2003,">="&$E$4,NOVEDADES!$B$4:$B$2003,"<="&$G$4))
...

Sheet NOVEDADES
A1: MATRIZ DE NOVEDADES DE LOGÍSTICA Y TRANSPORTE — GESTOAGRO S.A.S.
A2: Digite SOLO las celdas AMARILLAS. La llave es el # Pedido / Remisión (columna C): al escribirlo se traen cliente, destino, ruta, transportadora, transportador, placa y fecha de despacho. Las celdas GRISES no se tocan.
A3: Consecutivo | B3: Fecha novedad | C3: # Pedido / Remisión | D3: Cliente | E3: Destino / Ciudad | F3: Ruta | G3: Transportadora | H3: Transportador | I3: Placa | J3: Fecha despacho | K3: Verif. despacho | L3: Tipo de novedad | M3: Causa raíz | N3: Área responsable | O3: Responsable | P3: Criticidad | Q3: Cajas afectadas | R3: Valor afectado | S3: % del despacho | T3: Estado | U3: Fecha compromiso | V3: Fecha cierre real | W3: Días de gestión | X3: Días de mora | Y3: Semáforo SLA | Z3: Acción correctiva | AA3: Observaciones | AB3: Soporte / evidencia
A4: =IF($C4="","","NOV-"&TEXT(ROW()-3,"0000")) | D4: =IF($C4="","",IFERROR(INDEX(DESPACHOS!$D$3:$D$3002,MATCH($C4,DESPACHOS!$B$3:$B$3002,0)),"SIN DESPACHO")) | E4: =IF($C4="","",IFERROR(INDEX(DESPACHOS!$K$3:$K$3002,MATCH($C4,DESPACHOS!$B$3:$B$3002,0)),"")) | F4: =IF($C4="","",IFERROR(INDEX(DESPACHOS!$I$3:$I$3002,MATCH($C4,DESPACHOS!$B$3:$B$3002,0)),"")) | G4: =IF($C4="","",IFERROR(INDEX(DESPACHOS!$F$3:$F$3002,MATCH($C4,DESPACHOS!$B$3:$B$3002,0)),"")) | H4: =IF($C4="","",IFERROR(INDEX(DESPACHOS!$G$3:$G$3002,MATCH($C4,DESPACHOS!$B$3:$B$3002,0)),"")) | I4: =IF($C4="","",IFERROR(INDEX(DESPACHOS!$H$3:$H$3002,MATCH($C4,DESPACHOS!$B$3:$B$3002,0)),"")) | J4: =IF($C4="","",IFERROR(INDEX(DESPACHOS!$J$3:$J$3002,MATCH($C4,DESPACHOS!$B$3:$B$3002,0)),"")) | K4: =IF($C4="","",IF(COUNTIFS(DESPACHOS!$B$3:$B$3002,$C4)=0,"NO EXISTE",IF(COUNTIFS(DESPACHOS!$B$3:$B$3002,$C4)>1,"DUPLICADO","OK"))) | N4: =IF($M4="","",IFERROR(INDEX(LISTAS!$F$3:$F$42,MATCH($M4,LISTAS!$E$3:$E$42,0)),"Por definir")) | P4: =IF($L4="","",IFERROR(INDEX(LISTAS!$B$3:$B$42,MATCH($L4,LISTAS!$A$3:$A$42,0)),"Media")) | S4: =IFERROR(IF(OR($R4="",$C4=""),"",$R4/INDEX(DESPACHOS!$M$3:$M$3002,MATCH($C4,DESPACHOS!$B$3:$B$3002,0))),"") | U4: =IF(OR($B4="",$L4=""),"",WORKDAY($B4,IFERROR(INDEX(LISTAS!$C$3:$C$42,MATCH($L4,LISTAS!$A$3:$A$42,0)),3))) | W4: =IF($B4="","",IF($V4<>"",$V4-$B4,TODAY()-$B4)) | X4: =IF(OR($B4="",$U4=""),"",IF($V4<>"",MAX(0,$V4-$U4),MAX(0,TODAY()-$U4))) | Y4: =IF($C4="","",IF(IFERROR(INDEX(LISTAS!$I$3:$I$42,MATCH($T4,LISTAS!$H$3:$H$42,0)),"NO")="SÍ",IF(N($X4)>0,"CERRADA FUERA DE SLA","CERRADA EN SLA"),IF($U4="","SIN CLASIFICAR",IF(N($X4)>0,"VENCIDA",IF(TODAY()>=$U4-1,"POR VENCER","EN PLAZO")))))
A5: =IF($C5="","","NOV-"&TEXT(ROW()-3,"0000")) | D5: =IF($C5="","",IFERROR(INDEX(DESPACHOS!$D$3:$D$3002,MATCH($C5,DESPACHOS!$B$3:$B$3002,0)),"SIN DESPACHO")) | E5: =IF($C5="","",IFERROR(INDEX(DESPACHOS!$K$3:$K$3002,MATCH($C5,DESPACHOS!$B$3:$B$3002,0)),"")) | F5: =IF($C5="","",IFERROR(INDEX(DESPACHOS!$I$3:$I$3002,MATCH($C5,DESPACHOS!$B$3:$B$3002,0)),"")) | G5: =IF($C5="","",IFERROR(INDEX(DESPACHOS!$F$3:$F$3002,MATCH($C5,DESPACHOS!$B$3:$B$3002,0)),"")) | H5: =IF($C5="","",IFERROR(INDEX(DESPACHOS!$G$3:$G$3002,MATCH($C5,DESPACHOS!$B$3:$B$3002,0)),"")) | I5: =IF($C5="","",IFERROR(INDEX(DESPACHOS!$H$3:$H$3002,MATCH($C5,DESPACHOS!$B$3:$B$3002,0)),"")) | J5: =IF($C5="","",IFERROR(INDEX(DESPACHOS!$J$3:$J$3002,MATCH($C5,DESPACHOS!$B$3:$B$3002,0)),"")) | K5: =IF($C5="","",IF(COUNTIFS(DESPACHOS!$B$3:$B$3002,$C5)=0,"NO EXISTE",IF(COUNTIFS(DESPACHOS!$B$3:$B$3002,$C5)>1,"DUPLICADO","OK"))) | N5: =IF($M5="","",IFERROR(INDEX(LISTAS!$F$3:$F$42,MATCH($M5,LISTAS!$E$3:$E$42,0)),"Por definir")) | P5: =IF($L5="","",IFERROR(INDEX(LISTAS!$B$3:$B$42,MATCH($L5,LISTAS!$A$3:$A$42,0)),"Media")) | S5: =IFERROR(IF(OR($R5="",$C5=""),"",$R5/INDEX(DESPACHOS!$M$3:$M$3002,MATCH($C5,DESPACHOS!$B$3:$B$3002,0))),"") | U5: =IF(OR($B5="",$L5=""),"",WORKDAY($B5,IFERROR(INDEX(LISTAS!$C$3:$C$42,MATCH($L5,LISTAS!$A$3:$A$42,0)),3))) | W5: =IF($B5="","",IF($V5<>"",$V5-$B5,TODAY()-$B5)) | X5: =IF(OR($B5="",$U5=""),"",IF($V5<>"",MAX(0,$V5-$U5),MAX(0,TODAY()-$U5))) | Y5: =IF($C5="","",IF(IFERROR(INDEX(LISTAS!$I$3:$I$42,MATCH($T5,LISTAS!$H$3:$H$42,0)),"NO")="SÍ",IF(N($X5)>0,"CERRADA FUERA DE SLA","CERRADA EN SLA"),IF($U5="","SIN CLASIFICAR",IF(N($X5)>0,"VENCIDA",IF(TODAY()>=$U5-1,"POR VENCER","EN PLAZO")))))
A6: =IF($C6="","","NOV-"&TEXT(ROW()-3,"0000")) | D6: =IF($C6="","",IFERROR(INDEX(DESPACHOS!$D$3:$D$3002,MATCH($C6,DESPACHOS!$B$3:$B$3002,0)),"SIN DESPACHO")) | E6: =IF($C6="","",IFERROR(INDEX(DESPACHOS!$K$3:$K$3002,MATCH($C6,DESPACHOS!$B$3:$B$3002,0)),"")) | F6: =IF($C6="","",IFERROR(INDEX(DESPACHOS!$I$3:$I$3002,MATCH($C6,DESPACHOS!$B$3:$B$3002,0)),"")) | G6: =IF($C6="","",IFERROR(INDEX(DESPACHOS!$F$3:$F$3002,MATCH($C6,DESPACHOS!$B$3:$B$3002,0)),"")) | H6: =IF($C6="","",IFERROR(INDEX(DESPACHOS!$G$3:$G$3002,MATCH($C6,DESPACHOS!$B$3:$B$3002,0)),"")) | I6: =IF($C6="","",IFERROR(INDEX(DESPACHOS!$H$3:$H$3002,MATCH($C6,DESPACHOS!$B$3:$B$3002,0)),"")) | J6: =IF($C6="","",IFERROR(INDEX(DESPACHOS!$J$3:$J$3002,MATCH($C6,DESPACHOS!$B$3:$B$3002,0)),"")) | K6: =IF($C6="","",IF(COUNTIFS(DESPACHOS!$B$3:$B$3002,$C6)=0,"NO EXISTE",IF(COUNTIFS(DESPACHOS!$B$3:$B$3002,$C6)>1,"DUPLICADO","OK"))) | N6: =IF($M6="","",IFERROR(INDEX(LISTAS!$F$3:$F$42,MATCH($M6,LISTAS!$E$3:$E$42,0)),"Por definir")) | P6: =IF($L6="","",IFERROR(INDEX(LISTAS!$B$3:$B$42,MATCH($L6,LISTAS!$A$3:$A$42,0)),"Media")) | S6: =IFERROR(IF(OR($R6="",$C6=""),"",$R6/INDEX(DESPACHOS!$M$3:$M$3002,MATCH($C6,DESPACHOS!$B$3:$B$3002,0))),"") | U6: =IF(OR($B6="",$L6=""),"",WORKDAY($B6,IFERROR(INDEX(LISTAS!$C$3:$C$42,MATCH($L6,LISTAS!$A$3:$A$42,0)),3))) | W6: =IF($B6="","",IF($V6<>"",$V6-$B6,TODAY()-$B6)) | X6: =IF(OR($B6="",$U6=""),"",IF($V6<>"",MAX(0,$V6-$U6),MAX(0,TODAY()-$U6))) | Y6: =IF($C6="","",IF(IFERROR(INDEX(LISTAS!$I$3:$I$42,MATCH($T6,LISTAS!$H$3:$H$42,0)),"NO")="SÍ",IF(N($X6)>0,"CERRADA FUERA DE SLA","CERRADA EN SLA"),IF($U6="","SIN CLASIFICAR",IF(N($X6)>0,"VENCIDA",IF(TODAY()>=$U6-1,"POR VENCER","EN PLAZO")))))
A7: =IF($C7="","","NOV-"&TEXT(ROW()-3,"0000")) | D7: =IF($C7="","",IFERROR(INDEX(DESPACHOS!$D$3:$D$3002,MATCH($C7,DESPACHOS!$B$3:$B$3002,0)),"SIN DESPACHO")) | E7: =IF($C7="","",IFERROR(INDEX(DESPACHOS!$K$3:$K$3002,MATCH($C7,DESPACHOS!$B$3:$B$3002,0)),"")) | F7: =IF($C7="","",IFERROR(INDEX(DESPACHOS!$I$3:$I$3002,MATCH($C7,DESPACHOS!$B$3:$B$3002,0)),"")) | G7: =IF($C7="","",IFERROR(INDEX(DESPACHOS!$F$3:$F$3002,MATCH($C7,DESPACHOS!$B$3:$B$3002,0)),"")) | H7: =IF($C7="","",IFERROR(INDEX(DESPACHOS!$G$3:$G$3002,MATCH($C7,DESPACHOS!$B$3:$B$3002,0)),"")) | I7: =IF($C7="","",IFERROR(INDEX(DESPACHOS!$H$3:$H$3002,MATCH($C7,DESPACHOS!$B$3:$B$3002,0)),"")) | J7: =IF($C7="","",IFERROR(INDEX(DESPACHOS!$J$3:$J$3002,MATCH($C7,DESPACHOS!$B$3:$B$3002,0)),"")) | K7: =IF($C7="","",IF(COUNTIFS(DESPACHOS!$B$3:$B$3002,$C7)=0,"NO EXISTE",IF(COUNTIFS(DESPACHOS!$B$3:$B$3002,$C7)>1,"DUPLICADO","OK"))) | N7: =IF($M7="","",IFERROR(INDEX(LISTAS!$F$3:$F$42,MATCH($M7,LISTAS!$E$3:$E$42,0)),"Por definir")) | P7: =IF($L7="","",IFERROR(INDEX(LISTAS!$B$3:$B$42,MATCH($L7,LISTAS!$A$3:$A$42,0)),"Media")) | S7: =IFERROR(IF(OR($R7="",$C7=""),"",$R7/INDEX(DESPACHOS!$M$3:$M$3002,MATCH($C7,DESPACHOS!$B$3:$B$3002,0))),"") | U7: =IF(OR($B7="",$L7=""),"",WORKDAY($B7,IFERROR(INDEX(LISTAS!$C$3:$C$42,MATCH($L7,LISTAS!$A$3:$A$42,0)),3))) | W7: =IF($B7="","",IF($V7<>"",$V7-$B7,TODAY()-$B7)) | X7: =IF(OR($B7="",$U7=""),"",IF($V7<>"",MAX(0,$V7-$U7),MAX(0,TODAY()-$U7))) | Y7: =IF($C7="","",IF(IFERROR(INDEX(LISTAS!$I$3:$I$42,MATCH($T7,LISTAS!$H$3:$H$42,0)),"NO")="SÍ",IF(N($X7)>0,"CERRADA FUERA DE SLA","CERRADA EN SLA"),IF($U7="","SIN CLASIFICAR",IF(N($X7)>0,"VENCIDA",IF(TODAY()>=$U7-1,"POR VENCER","EN PLAZO")))))
A8: =IF($C8="","","NOV-"&TEXT(ROW()-3,"0000")) | D8: =IF($C8="","",IFERROR(INDEX(DESPACHOS!$D$3:$D$3002,MATCH($C8,DESPACHOS!$B$3:$B$3002,0)),"SIN DESPACHO")) | E8: =IF($C8="","",IFERROR(INDEX(DESPACHOS!$K$3:$K$3002,MATCH($C8,DESPACHOS!$B$3:$B$3002,0)),"")) | F8: =IF($C8="","",IFERROR(INDEX(DESPACHOS!$I$3:$I$3002,MATCH($C8,DESPACHOS!$B$3:$B$3002,0)),"")) | G8: =IF($C8="","",IFERROR(INDEX(DESPACHOS!$F$3:$F$3002,MATCH($C8,DESPACHOS!$B$3:$B$3002,0)),"")) | H8: =IF($C8="","",IFERROR(INDEX(DESPACHOS!$G$3:$G$3002,MATCH($C8,DESPACHOS!$B$3:$B$3002,0)),"")) | I8: =IF($C8="","",IFERROR(INDEX(DESPACHOS!$H$3:$H$3002,MATCH($C8,DESPACHOS!$B$3:$B$3002,0)),"")) | J8: =IF($C8="","",IFERROR(INDEX(DESPACHOS!$J$3:$J$3002,MATCH($C8,DESPACHOS!$B$3:$B$3002,0)),"")) | K8: =IF($C8="","",IF(COUNTIFS(DESPACHOS!$B$3:$B$3002,$C8)=0,"NO EXISTE",IF(COUNTIFS(DESPACHOS!$B$3:$B$3002,$C8)>1,"DUPLICADO","OK"))) | N8: =IF($M8="","",IFERROR(INDEX(LISTAS!$F$3:$F$42,MATCH($M8,LISTAS!$E$3:$E$42,0)),"Por definir")) | P8: =IF($L8="","",IFERROR(INDEX(LISTAS!$B$3:$B$42,MATCH($L8,LISTAS!$A$3:$A$42,0)),"Media")) | S8: =IFERROR(IF(OR($R8="",$C8=""),"",$R8/INDEX(DESPACHOS!$M$3:$M$3002,MATCH($C8,DESPACHOS!$B$3:$B$3002,0))),"") | U8: =IF(OR($B8="",$L8=""),"",WORKDAY($B8,IFERROR(INDEX(LISTAS!$C$3:$C$42,MATCH($L8,LISTAS!$A$3:$A$42,0)),3))) | W8: =IF($B8="","",IF($V8<>"",$V8-$B8,TODAY()-$B8)) | X8: =IF(OR($B8="",$U8=""),"",IF($V8<>"",MAX(0,$V8-$U8),MAX(0,TODAY()-$U8))) | Y8: =IF($C8="","",IF(IFERROR(INDEX(LISTAS!$I$3:$I$42,MATCH($T8,LISTAS!$H$3:$H$42,0)),"NO")="SÍ",IF(N($X8)>0,"CERRADA FUERA DE SLA","CERRADA EN SLA"),IF($U8="","SIN CLASIFICAR",IF(N($X8)>0,"VENCIDA",IF(TODAY()>=$U8-1,"POR VENCER","EN PLAZO")))))
A9: =IF($C9="","","NOV-"&TEXT(ROW()-3,"0000")) | D9: =IF($C9="","",IFERROR(INDEX(DESPACHOS!$D$3:$D$3002,MATCH($C9,DESPACHOS!$B$3:$B$3002,0)),"SIN DESPACHO")) | E9: =IF($C9="","",IFERROR(INDEX(DESPACHOS!$K$3:$K$3002,MATCH($C9,DESPACHOS!$B$3:$B$3002,0)),"")) | F9: =IF($C9="","",IFERROR(INDEX(DESPACHOS!$I$3:$I$3002,MATCH($C9,DESPACHOS!$B$3:$B$3002,0)),"")) | G9: =IF($C9="","",IFERROR(INDEX(DESPACHOS!$F$3:$F$3002,MATCH($C9,DESPACHOS!$B$3:$B$3002,0)),"")) | H9: =IF($C9="","",IFERROR(INDEX(DESPACHOS!$G$3:$G$3002,MATCH($C9,DESPACHOS!$B$3:$B$3002,0)),"")) | I9: =IF($C9="","",IFERROR(INDEX(DESPACHOS!$H$3:$H$3002,MATCH($C9,DESPACHOS!$B$3:$B$3002,0)),"")) | J9: =IF($C9="","",IFERROR(INDEX(DESPACHOS!$J$3:$J$3002,MATCH($C9,DESPACHOS!$B$3:$B$3002,0)),"")) | K9: =IF($C9="","",IF(COUNTIFS(DESPACHOS!$B$3:$B$3002,$C9)=0,"NO EXISTE",IF(COUNTIFS(DESPACHOS!$B$3:$B$3002,$C9)>1,"DUPLICADO","OK"))) | N9: =IF($M9="","",IFERROR(INDEX(LISTAS!$F$3:$F$42,MATCH($M9,LISTAS!$E$3:$E$42,0)),"Por definir")) | P9: =IF($L9="","",IFERROR(INDEX(LISTAS!$B$3:$B$42,MATCH($L9,LISTAS!$A$3:$A$42,0)),"Media")) | S9: =IFERROR(IF(OR($R9="",$C9=""),"",$R9/INDEX(DESPACHOS!$M$3:$M$3002,MATCH($C9,DESPACHOS!$B$3:$B$3002,0))),"") | U9: =IF(OR($B9="",$L9=""),"",WORKDAY($B9,IFERROR(INDEX(LISTAS!$C$3:$C$42,MATCH($L9,LISTAS!$A$3:$A$42,0)),3))) | W9: =IF($B9="","",IF($V9<>"",$V9-$B9,TODAY()-$B9)) | X9: =IF(OR($B9="",$U9=""),"",IF($V9<>"",MAX(0,$V9-$U9),MAX(0,TODAY()-$U9))) | Y9: =IF($C9="","",IF(IFERROR(INDEX(LISTAS!$I$3:$I$42,MATCH($T9,LISTAS!$H$3:$H$42,0)),"NO")="SÍ",IF(N($X9)>0,"CERRADA FUERA DE SLA","CERRADA EN SLA"),IF($U9="","SIN CLASIFICAR",IF(N($X9)>0,"VENCIDA",IF(TODAY()>=$U9-1,"POR VENCER","EN PLAZO")))))
A10: =IF($C10="","","NOV-"&TEXT(ROW()-3,"0000")) | D10: =IF($C10="","",IFERROR(INDEX(DESPACHOS!$D$3:$D$3002,MATCH($C10,DESPACHOS!$B$3:$B$3002,0)),"SIN DESPACHO")) | E10: =IF($C10="","",IFERROR(INDEX(DESPACHOS!$K$3:$K$3002,MATCH($C10,DESPACHOS!$B$3:$B$3002,0)),"")) | F10: =IF($C10="","",IFERROR(INDEX(DESPACHOS!$I$3:$I$3002,MATCH($C10,DESPACHOS!$B$3:$B$3002,0)),"")) | G10: =IF($C10="","",IFERROR(INDEX(DESPACHOS!$F$3:$F$3002,MATCH($C10,DESPACHOS!$B$3:$B$3002,0)),"")) | H10: =IF($C10="","",IFERROR(INDEX(DESPACHOS!$G$3:$G$3002,MATCH($C10,DESPACHOS!$B$3:$B$3002,0)),"")) | I10: =IF($C10="","",IFERROR(INDEX(DESPACHOS!$H$3:$H$3002,MATCH($C10,DESPACHOS!$B$3:$B$3002,0)),"")) | J10: =IF($C10="","",IFERROR(INDEX(DESPACHOS!$J$3:$J$3002,MATCH($C10,DESPACHOS!$B$3:$B$3002,0)),"")) | K10: =IF($C10="","",IF(COUNTIFS(DESPACHOS!$B$3:$B$3002,$C10)=0,"NO EXISTE",IF(COUNTIFS(DESPACHOS!$B$3:$B$3002,$C10)>1,"DUPLICADO","OK"))) | N10: =IF($M10="","",IFERROR(INDEX(LISTAS!$F$3:$F$42,MATCH($M10,LISTAS!$E$3:$E$42,0)),"Por definir")) | P10: =IF($L10="","",IFERROR(INDEX(LISTAS!$B$3:$B$42,MATCH($L10,LISTAS!$A$3:$A$42,0)),"Media")) | S10: =IFERROR(IF(OR($R10="",$C10=""),"",$R10/INDEX(DESPACHOS!$M$3:$M$3002,MATCH($C10,DESPACHOS!$B$3:$B$3002,0))),"") | U10: =IF(OR($B10="",$L10=""),"",WORKDAY($B10,IFERROR(INDEX(LISTAS!$C$3:$C$42,MATCH($L10,LISTAS!$A$3:$A$42,0)),3))) | W10: =IF($B10="","",IF($V10<>"",$V10-$B10,TODAY()-$B10)) | X10: =IF(OR($B10="",$U10=""),"",IF($V10<>"",MAX(0,$V10-$U10),MAX(0,TODAY()-$U10))) | Y10: =IF($C10="","",IF(IFERROR(INDEX(LISTAS!$I$3:$I$42,MATCH($T10,LISTAS!$H$3:$H$42,0)),"NO")="SÍ",IF(N($X10)>0,"CERRADA FUERA DE SLA","CERRADA EN SLA"),IF($U10="","SIN CLASIFICAR",IF(N($X10)>0,"VENCIDA",IF(TODAY()>=$U10-1,"POR VENCER","EN PLAZO")))))
A11: =IF($C11="","","NOV-"&TEXT(ROW()-3,"0000")) | D11: =IF($C11="","",IFERROR(INDEX(DESPACHOS!$D$3:$D$3002,MATCH($C11,DESPACHOS!$B$3:$B$3002,0)),"SIN DESPACHO")) | E11: =IF($C11="","",IFERROR(INDEX(DESPACHOS!$K$3:$K$3002,MATCH($C11,DESPACHOS!$B$3:$B$3002,0)),"")) | F11: =IF($C11="","",IFERROR(INDEX(DESPACHOS!$I$3:$I$3002,MATCH($C11,DESPACHOS!$B$3:$B$3002,0)),"")) | G11: =IF($C11="","",IFERROR(INDEX(DESPACHOS!$F$3:$F$3002,MATCH($C11,DESPACHOS!$B$3:$B$3002,0)),"")) | H11: =IF($C11="","",IFERROR(INDEX(DESPACHOS!$G$3:$G$3002,MATCH($C11,DESPACHOS!$B$3:$B$3002,0)),"")) | I11: =IF($C11="","",IFERROR(INDEX(DESPACHOS!$H$3:$H$3002,MATCH($C11,DESPACHOS!$B$3:$B$3002,0)),"")) | J11: =IF($C11="","",IFERROR(INDEX(DESPACHOS!$J$3:$J$3002,MATCH($C11,DESPACHOS!$B$3:$B$3002,0)),"")) | K11: =IF($C11="","",IF(COUNTIFS(DESPACHOS!$B$3:$B$3002,$C11)=0,"NO EXISTE",IF(COUNTIFS(DESPACHOS!$B$3:$B$3002,$C11)>1,"DUPLICADO","OK"))) | N11: =IF($M11="","",IFERROR(INDEX(LISTAS!$F$3:$F$42,MATCH($M11,LISTAS!$E$3:$E$42,0)),"Por definir")) | P11: =IF($L11="","",IFERROR(INDEX(LISTAS!$B$3:$B$42,MATCH($L11,LISTAS!$A$3:$A$42,0)),"Media")) | S11: =IFERROR(IF(OR($R11="",$C11=""),"",$R11/INDEX(DESPACHOS!$M$3:$M$3002,MATCH($C11,DESPACHOS!$B$3:$B$3002,0))),"") | U11: =IF(OR($B11="",$L11=""),"",WORKDAY($B11,IFERROR(INDEX(LISTAS!$C$3:$C$42,MATCH($L11,LISTAS!$A$3:$A$42,0)),3))) | W11: =IF($B11="","",IF($V11<>"",$V11-$B11,TODAY()-$B11)) | X11: =IF(OR($B11="",$U11=""),"",IF($V11<>"",MAX(0,$V11-$U11),MAX(0,TODAY()-$U11))) | Y11: =IF($C11="","",IF(IFERROR(INDEX(LISTAS!$I$3:$I$42,MATCH($T11,LISTAS!$H$3:$H$42,0)),"NO")="SÍ",IF(N($X11)>0,"CERRADA FUERA DE SLA","CERRADA EN SLA"),IF($U11="","SIN CLASIFICAR",IF(N($X11)>0,"VENCIDA",IF(TODAY()>=$U11-1,"POR VENCER","EN PLAZO")))))
A12: =IF($C12="","","NOV-"&TEXT(ROW()-3,"0000")) | D12: =IF($C12="","",IFERROR(INDEX(DESPACHOS!$D$3:$D$3002,MATCH($C12,DESPACHOS!$B$3:$B$3002,0)),"SIN DESPACHO")) | E12: =IF($C12="","",IFERROR(INDEX(DESPACHOS!$K$3:$K$3002,MATCH($C12,DESPACHOS!$B$3:$B$3002,0)),"")) | F12: =IF($C12="","",IFERROR(INDEX(DESPACHOS!$I$3:$I$3002,MATCH($C12,DESPACHOS!$B$3:$B$3002,0)),"")) | G12: =IF($C12="","",IFERROR(INDEX(DESPACHOS!$F$3:$F$3002,MATCH($C12,DESPACHOS!$B$3:$B$3002,0)),"")) | H12: =IF($C12="","",IFERROR(INDEX(DESPACHOS!$G$3:$G$3002,MATCH($C12,DESPACHOS!$B$3:$B$3002,0)),"")) | I12: =IF($C12="","",IFERROR(INDEX(DESPACHOS!$H$3:$H$3002,MATCH($C12,DESPACHOS!$B$3:$B$3002,0)),"")) | J12: =IF($C12="","",IFERROR(INDEX(DESPACHOS!$J$3:$J$3002,MATCH($C12,DESPACHOS!$B$3:$B$3002,0)),"")) | K12: =IF($C12="","",IF(COUNTIFS(DESPACHOS!$B$3:$B$3002,$C12)=0,"NO EXISTE",IF(COUNTIFS(DESPACHOS!$B$3:$B$3002,$C12)>1,"DUPLICADO","OK"))) | N12: =IF($M12="","",IFERROR(INDEX(LISTAS!$F$3:$F$42,MATCH($M12,LISTAS!$E$3:$E$42,0)),"Por definir")) | P12: =IF($L12="","",IFERROR(INDEX(LISTAS!$B$3:$B$42,MATCH($L12,LISTAS!$A$3:$A$42,0)),"Media")) | S12: =IFERROR(IF(OR($R12="",$C12=""),"",$R12/INDEX(DESPACHOS!$M$3:$M$3002,MATCH($C12,DESPACHOS!$B$3:$B$3002,0))),"") | U12: =IF(OR($B12="",$L12=""),"",WORKDAY($B12,IFERROR(INDEX(LISTAS!$C$3:$C$42,MATCH($L12,LISTAS!$A$3:$A$42,0)),3))) | W12: =IF($B12="","",IF($V12<>"",$V12-$B12,TODAY()-$B12)) | X12: =IF(OR($B12="",$U12=""),"",IF($V12<>"",MAX(0,$V12-$U12),MAX(0,TODAY()-$U12))) | Y12: =IF($C12="","",IF(IFERROR(INDEX(LISTAS!$I$3:$I$42,MATCH($T12,LISTAS!$H$3:$H$42,0)),"NO")="SÍ",IF(N($X12)>0,"CERRADA FUERA DE SLA","CERRADA EN SLA"),IF($U12="","SIN CLASIFICAR",IF(N($X12)>0,"VENCIDA",IF(TODAY()>=$U12-1,"POR VENCER","EN PLAZO")))))
A13: =IF($C13="","","NOV-"&TEXT(ROW()-3,"0000")) | D13: =IF($C13="","",IFERROR(INDEX(DESPACHOS!$D$3:$D$3002,MATCH($C13,DESPACHOS!$B$3:$B$3002,0)),"SIN DESPACHO")) | E13: =IF($C13="","",IFERROR(INDEX(DESPACHOS!$K$3:$K$3002,MATCH($C13,DESPACHOS!$B$3:$B$3002,0)),"")) | F13: =IF($C13="","",IFERROR(INDEX(DESPACHOS!$I$3:$I$3002,MATCH($C13,DESPACHOS!$B$3:$B$3002,0)),"")) | G13: =IF($C13="","",IFERROR(INDEX(DESPACHOS!$F$3:$F$3002,MATCH($C13,DESPACHOS!$B$3:$B$3002,0)),"")) | H13: =IF($C13="","",IFERROR(INDEX(DESPACHOS!$G$3:$G$3002,MATCH($C13,DESPACHOS!$B$3:$B$3002,0)),"")) | I13: =IF($C13="","",IFERROR(INDEX(DESPACHOS!$H$3:$H$3002,MATCH($C13,DESPACHOS!$B$3:$B$3002,0)),"")) | J13: =IF($C13="","",IFERROR(INDEX(DESPACHOS!$J$3:$J$3002,MATCH($C13,DESPACHOS!$B$3:$B$3002,0)),"")) | K13: =IF($C13="","",IF(COUNTIFS(DESPACHOS!$B$3:$B$3002,$C13)=0,"NO EXISTE",IF(COUNTIFS(DESPACHOS!$B$3:$B$3002,$C13)>1,"DUPLICADO","OK"))) | N13: =IF($M13="","",IFERROR(INDEX(LISTAS!$F$3:$F$42,MATCH($M13,LISTAS!$E$3:$E$42,0)),"Por definir")) | P13: =IF($L13="","",IFERROR(INDEX(LISTAS!$B$3:$B$42,MATCH($L13,LISTAS!$A$3:$A$42,0)),"Media")) | S13: =IFERROR(IF(OR($R13="",$C13=""),"",$R13/INDEX(DESPACHOS!$M$3:$M$3002,MATCH($C13,DESPACHOS!$B$3:$B$3002,0))),"") | U13: =IF(OR($B13="",$L13=""),"",WORKDAY($B13,IFERROR(INDEX(LISTAS!$C$3:$C$42,MATCH($L13,LISTAS!$A$3:$A$42,0)),3))) | W13: =IF($B13="","",IF($V13<>"",$V13-$B13,TODAY()-$B13)) | X13: =IF(OR($B13="",$U13=""),"",IF($V13<>"",MAX(0,$V13-$U13),MAX(0,TODAY()-$U13))) | Y13: =IF($C13="","",IF(IFERROR(INDEX(LISTAS!$I$3:$I$42,MATCH($T13,LISTAS!$H$3:$H$42,0)),"NO")="SÍ",IF(N($X13)>0,"CERRADA FUERA DE SLA","CERRADA EN SLA"),IF($U13="","SIN CLASIFICAR",IF(N($X13)>0,"VENCIDA",IF(TODAY()>=$U13-1,"POR VENCER","EN PLAZO")))))
A14: =IF($C14="","","NOV-"&TEXT(ROW()-3,"0000")) | D14: =IF($C14="","",IFERROR(INDEX(DESPACHOS!$D$3:$D$3002,MATCH($C14,DESPACHOS!$B$3:$B$3002,0)),"SIN DESPACHO")) | E14: =IF($C14="","",IFERROR(INDEX(DESPACHOS!$K$3:$K$3002,MATCH($C14,DESPACHOS!$B$3:$B$3002,0)),"")) | F14: =IF($C14="","",IFERROR(INDEX(DESPACHOS!$I$3:$I$3002,MATCH($C14,DESPACHOS!$B$3:$B$3002,0)),"")) | G14: =IF($C14="","",IFERROR(INDEX(DESPACHOS!$F$3:$F$3002,MATCH($C14,DESPACHOS!$B$3:$B$3002,0)),"")) | H14: =IF($C14="","",IFERROR(INDEX(DESPACHOS!$G$3:$G$3002,MATCH($C14,DESPACHOS!$B$3:$B$3002,0)),"")) | I14: =IF($C14="","",IFERROR(INDEX(DESPACHOS!$H$3:$H$3002,MATCH($C14,DESPACHOS!$B$3:$B$3002,0)),"")) | J14: =IF($C14="","",IFERROR(INDEX(DESPACHOS!$J$3:$J$3002,MATCH($C14,DESPACHOS!$B$3:$B$3002,0)),"")) | K14: =IF($C14="","",IF(COUNTIFS(DESPACHOS!$B$3:$B$3002,$C14)=0,"NO EXISTE",IF(COUNTIFS(DESPACHOS!$B$3:$B$3002,$C14)>1,"DUPLICADO","OK"))) | N14: =IF($M14="","",IFERROR(INDEX(LISTAS!$F$3:$F$42,MATCH($M14,LISTAS!$E$3:$E$42,0)),"Por definir")) | P14: =IF($L14="","",IFERROR(INDEX(LISTAS!$B$3:$B$42,MATCH($L14,LISTAS!$A$3:$A$42,0)),"Media")) | S14: =IFERROR(IF(OR($R14="",$C14=""),"",$R14/INDEX(DESPACHOS!$M$3:$M$3002,MATCH($C14,DESPACHOS!$B$3:$B$3002,0))),"") | U14: =IF(OR($B14="",$L14=""),"",WORKDAY($B14,IFERROR(INDEX(LISTAS!$C$3:$C$42,MATCH($L14,LISTAS!$A$3:$A$42,0)),3))) | W14: =IF($B14="","",IF($V14<>"",$V14-$B14,TODAY()-$B14)) | X14: =IF(OR($B14="",$U14=""),"",IF($V14<>"",MAX(0,$V14-$U14),MAX(0,TODAY()-$U14))) | Y14: =IF($C14="","",IF(IFERROR(INDEX(LISTAS!$I$3:$I$42,MATCH($T14,LISTAS!$H$3:$H$42,0)),"NO")="SÍ",IF(N($X14)>0,"CERRADA FUERA DE SLA","CERRADA EN SLA"),IF($U14="","SIN CLASIFICAR",IF(N($X14)>0,"VENCIDA",IF(TODAY()>=$U14-1,"POR VENCER","EN PLAZO")))))
A15: =IF($C15="","","NOV-"&TEXT(ROW()-3,"0000")) | D15: =IF($C15="","",IFERROR(INDEX(DESPACHOS!$D$3:$D$3002,MATCH($C15,DESPACHOS!$B$3:$B$3002,0)),"SIN DESPACHO")) | E15: =IF($C15="","",IFERROR(INDEX(DESPACHOS!$K$3:$K$3002,MATCH($C15,DESPACHOS!$B$3:$B$3002,0)),"")) | F15: =IF($C15="","",IFERROR(INDEX(DESPACHOS!$I$3:$I$3002,MATCH($C15,DESPACHOS!$B$3:$B$3002,0)),"")) | G15: =IF($C15="","",IFERROR(INDEX(DESPACHOS!$F$3:$F$3002,MATCH($C15,DESPACHOS!$B$3:$B$3002,0)),"")) | H15: =IF($C15="","",IFERROR(INDEX(DESPACHOS!$G$3:$G$3002,MATCH($C15,DESPACHOS!$B$3:$B$3002,0)),"")) | I15: =IF($C15="","",IFERROR(INDEX(DESPACHOS!$H$3:$H$3002,MATCH($C15,DESPACHOS!$B$3:$B$3002,0)),"")) | J15: =IF($C15="","",IFERROR(INDEX(DESPACHOS!$J$3:$J$3002,MATCH($C15,DESPACHOS!$B$3:$B$3002,0)),"")) | K15: =IF($C15="","",IF(COUNTIFS(DESPACHOS!$B$3:$B$3002,$C15)=0,"NO EXISTE",IF(COUNTIFS(DESPACHOS!$B$3:$B$3002,$C15)>1,"DUPLICADO","OK"))) | N15: =IF($M15="","",IFERROR(INDEX(LISTAS!$F$3:$F$42,MATCH($M15,LISTAS!$E$3:$E$42,0)),"Por definir")) | P15: =IF($L15="","",IFERROR(INDEX(LISTAS!$B$3:$B$42,MATCH($L15,LISTAS!$A$3:$A$42,0)),"Media")) | S15: =IFERROR(IF(OR($R15="",$C15=""),"",$R15/INDEX(DESPACHOS!$M$3:$M$3002,MATCH($C15,DESPACHOS!$B$3:$B$3002,0))),"") | U15: =IF(OR($B15="",$L15=""),"",WORKDAY($B15,IFERROR(INDEX(LISTAS!$C$3:$C$42,MATCH($L15,LISTAS!$A$3:$A$42,0)),3))) | W15: =IF($B15="","",IF($V15<>"",$V15-$B15,TODAY()-$B15)) | X15: =IF(OR($B15="",$U15=""),"",IF($V15<>"",MAX(0,$V15-$U15),MAX(0,TODAY()-$U15))) | Y15: =IF($C15="","",IF(IFERROR(INDEX(LISTAS!$I$3:$I$42,MATCH($T15,LISTAS!$H$3:$H$42,0)),"NO")="SÍ",IF(N($X15)>0,"CERRADA FUERA DE SLA","CERRADA EN SLA"),IF($U15="","SIN CLASIFICAR",IF(N($X15)>0,"VENCIDA",IF(TODAY()>=$U15-1,"POR VENCER","EN PLAZO")))))
... A2003: =IF($C2003="","","NOV-"&TEXT(ROW()-3,"0000")) | D2003: =IF($C2003="","",IFERROR(INDEX(DESPACHOS!$D$3:$D$3002,MATCH($C2003,DESPACHOS!$B$3:$B$3002,0)),"SIN DESPACHO")) | E2003: =IF($C2003="","",IFERROR(INDEX(DESPACHOS!$K$3:$K$3002,MATCH($C2003,DESPACHOS!$B$3:$B$3002,0)),"")) | F2003: =IF($C2003="","",IFERROR(INDEX(DESPACHOS!$I$3:$I$3002,MATCH($C2003,DESPACHOS!$B$3:$B$3002,0)),"")) | G2003: =IF($C2003="","",IFERROR(INDEX(DESPACHOS!$F$3:$F$3002,MATCH($C2003,DESPACHOS!$B$3:$B$3002,0)),"")) | H2003: =IF($C2003="","",IFERROR(INDEX(DESPACHOS!$G$3:$G$3002,MATCH($C2003,DESPACHOS!$B$3:$B$3002,0)),"")) | I2003: =IF($C2003="","",IFERROR(INDEX(DESPACHOS!$H$3:$H$3002,MATCH($C2003,DESPACHOS!$B$3:$B$3002,0)),"")) | J2003: =IF($C2003="","",IFERROR(INDEX(DESPACHOS!$J$3:$J$3002,MATCH($C2003,DESPACHOS!$B$3:$B$3002,0)),"")) | K2003: =IF($C2003="","",IF(COUNTIFS(DESPACHOS!$B$3:$B$3002,$C2003)=0,"NO EXISTE",IF(COUNTIFS(DESPACHOS!$B$3:$B$3002,$C2003)>1,"DUPLICADO","OK"))) | N2003: =IF($M2003="","",IFERROR(INDEX(LISTAS!$F$3:$F$42,MATCH($M2003,LISTAS!$E$3:$E$42,0)),"Por definir")) | P2003: =IF($L2003="","",IFERROR(INDEX(LISTAS!$B$3:$B$42,MATCH($L2003,LISTAS!$A$3:$A$42,0)),"Media")) | S2003: =IFERROR(IF(OR($R2003="",$C2003=""),"",$R2003/INDEX(DESPACHOS!$M$3:$M$3002,MATCH($C2003,DESPACHOS!$B$3:$B$3002,0))),"") | U2003: =IF(OR($B2003="",$L2003=""),"",WORKDAY($B2003,IFERROR(INDEX(LISTAS!$C$3:$C$42,MATCH($L2003,LISTAS!$A$3:$A$42,0)),3))) | W2003: =IF($B2003="","",IF($V2003<>"",$V2003-$B2003,TODAY()-$B2003)) | X2003: =IF(OR($B2003="",$U2003=""),"",IF($V2003<>"",MAX(0,$V2003-$U2003),MAX(0,TODAY()-$U2003))) | Y2003: =IF($C2003="","",IF(IFERROR(INDEX(LISTAS!$I$3:$I$42,MATCH($T2003,LISTAS!$H$3:$H$42,0)),"NO")="SÍ",IF(N($X2003)>0,"CERRADA FUERA DE SLA","CERRADA EN SLA"),IF($U2003="","SIN CLASIFICAR",IF(N($X2003)>0,"VENCIDA",IF(TODAY()>=$U2003-1,"POR VENCER","EN PLAZO")))))

Sheet DESPACHOS
A1: DESPACHOS / BASE — pegue aquí el export de Access desde la fila 3 (columnas A a J). K, L y M se digitan; N y O se calculan solas.
A2: # Planilla | B2: # Pedido / Remisión | C2: # Factura | D2: Cliente | E2: Peso KG | F2: Transportadora | G2: Transportador | H2: Placa | I2: Ruta | J2: Fecha despacho | K2: Destino / Ciudad | L2: Cajas enviadas | M2: Valor despachado | N2: Zona SLA | O2: ¿Tiene novedad?
N3: =IF($B3="","",IF(SUMPRODUCT((LISTAS!$O$3:$O$42<>"")*ISNUMBER(SEARCH(LISTAS!$O$3:$O$42,$I3&" "&$K3)))>0,"CERCANA","NACIONAL")) | O3: =IF($B3="","",IF(COUNTIFS(NOVEDADES!$C$4:$C$2003,$B3)=0,"—","SÍ ("&COUNTIFS(NOVEDADES!$C$4:$C$2003,$B3)&")"))
N4: =IF($B4="","",IF(SUMPRODUCT((LISTAS!$O$3:$O$42<>"")*ISNUMBER(SEARCH(LISTAS!$O$3:$O$42,$I4&" "&$K4)))>0,"CERCANA","NACIONAL")) | O4: =IF($B4="","",IF(COUNTIFS(NOVEDADES!$C$4:$C$2003,$B4)=0,"—","SÍ ("&COUNTIFS(NOVEDADES!$C$4:$C$2003,$B4)&")"))
N5: =IF($B5="","",IF(SUMPRODUCT((LISTAS!$O$3:$O$42<>"")*ISNUMBER(SEARCH(LISTAS!$O$3:$O$42,$I5&" "&$K5)))>0,"CERCANA","NACIONAL")) | O5: =IF($B5="","",IF(COUNTIFS(NOVEDADES!$C$4:$C$2003,$B5)=0,"—","SÍ ("&COUNTIFS(NOVEDADES!$C$4:$C$2003,$B5)&")"))
N6: =IF($B6="","",IF(SUMPRODUCT((LISTAS!$O$3:$O$42<>"")*ISNUMBER(SEARCH(LISTAS!$O$3:$O$42,$I6&" "&$K6)))>0,"CERCANA","NACIONAL")) | O6: =IF($B6="","",IF(COUNTIFS(NOVEDADES!$C$4:$C$2003,$B6)=0,"—","SÍ ("&COUNTIFS(NOVEDADES!$C$4:$C$2003,$B6)&")"))
N7: =IF($B7="","",IF(SUMPRODUCT((LISTAS!$O$3:$O$42<>"")*ISNUMBER(SEARCH(LISTAS!$O$3:$O$42,$I7&" "&$K7)))>0,"CERCANA","NACIONAL")) | O7: =IF($B7="","",IF(COUNTIFS(NOVEDADES!$C$4:$C$2003,$B7)=0,"—","SÍ ("&COUNTIFS(NOVEDADES!$C$4:$C$2003,$B7)&")"))
N8: =IF($B8="","",IF(SUMPRODUCT((LISTAS!$O$3:$O$42<>"")*ISNUMBER(SEARCH(LISTAS!$O$3:$O$42,$I8&" "&$K8)))>0,"CERCANA","NACIONAL")) | O8: =IF($B8="","",IF(COUNTIFS(NOVEDADES!$C$4:$C$2003,$B8)=0,"—","SÍ ("&COUNTIFS(NOVEDADES!$C$4:$C$2003,$B8)&")"))
N9: =IF($B9="","",IF(SUMPRODUCT((LISTAS!$O$3:$O$42<>"")*ISNUMBER(SEARCH(LISTAS!$O$3:$O$42,$I9&" "&$K9)))>0,"CERCANA","NACIONAL")) | O9: =IF($B9="","",IF(COUNTIFS(NOVEDADES!$C$4:$C$2003,$B9)=0,"—","SÍ ("&COUNTIFS(NOVEDADES!$C$4:$C$2003,$B9)&")"))
N10: =IF($B10="","",IF(SUMPRODUCT((LISTAS!$O$3:$O$42<>"")*ISNUMBER(SEARCH(LISTAS!$O$3:$O$42,$I10&" "&$K10)))>0,"CERCANA","NACIONAL")) | O10: =IF($B10="","",IF(COUNTIFS(NOVEDADES!$C$4:$C$2003,$B10)=0,"—","SÍ ("&COUNTIFS(NOVEDADES!$C$4:$C$2003,$B10)&")"))
N11: =IF($B11="","",IF(SUMPRODUCT((LISTAS!$O$3:$O$42<>"")*ISNUMBER(SEARCH(LISTAS!$O$3:$O$42,$I11&" "&$K11)))>0,"CERCANA","NACIONAL")) | O11: =IF($B11="","",IF(COUNTIFS(NOVEDADES!$C$4:$C$2003,$B11)=0,"—","SÍ ("&COUNTIFS(NOVEDADES!$C$4:$C$2003,$B11)&")"))
N12: =IF($B12="","",IF(SUMPRODUCT((LISTAS!$O$3:$O$42<>"")*ISNUMBER(SEARCH(LISTAS!$O$3:$O$42,$I12&" "&$K12)))>0,"CERCANA","NACIONAL")) | O12: =IF($B12="","",IF(COUNTIFS(NOVEDADES!$C$4:$C$2003,$B12)=0,"—","SÍ ("&COUNTIFS(NOVEDADES!$C$4:$C$2003,$B12)&")"))
N13: =IF($B13="","",IF(SUMPRODUCT((LISTAS!$O$3:$O$42<>"")*ISNUMBER(SEARCH(LISTAS!$O$3:$O$42,$I13&" "&$K13)))>0,"CERCANA","NACIONAL")) | O13: =IF($B13="","",IF(COUNTIFS(NOVEDADES!$C$4:$C$2003,$B13)=0,"—","SÍ ("&COUNTIFS(NOVEDADES!$C$4:$C$2003,$B13)&")"))
N14: =IF($B14="","",IF(SUMPRODUCT((LISTAS!$O$3:$O$42<>"")*ISNUMBER(SEARCH(LISTAS!$O$3:$O$42,$I14&" "&$K14)))>0,"CERCANA","NACIONAL")) | O14: =IF($B14="","",IF(COUNTIFS(NOVEDADES!$C$4:$C$2003,$B14)=0,"—","SÍ ("&COUNTIFS(NOVEDADES!$C$4:$C$2003,$B14)&")"))
... N3002: =IF($B3002="","",IF(SUMPRODUCT((LISTAS!$O$3:$O$42<>"")*ISNUMBER(SEARCH(LISTAS!$O$3:$O$42,$I3002&" "&$K3002)))>0,"CERCANA","NACIONAL")) | O3002: =IF($B3002="","",IF(COUNTIFS(NOVEDADES!$C$4:$C$2003,$B3002)=0,"—","SÍ ("&COUNTIFS(NOVEDADES!$C$4:$C$2003,$B3002)&")"))

Sheet LISTAS
A1: CATÁLOGOS Y REGLAS DE NEGOCIO — no borre encabezados, agregue filas hacia abajo
A2: TIPO DE NOVEDAD | B2: CRITICIDAD | C2: SLA (días hábiles) | E2: CAUSA RAÍZ | F2: ÁREA RESPONSABLE | H2: ESTADO | I2: ¿CIERRA? (SÍ/NO) | K2: TRANSPORTADORA | M2: RESPONSABLE | O2: ZONA CERCANA (SLA corto) | Q2: PLAZO ZONA CERCANA (días) | R2: PLAZO NACIONAL (días)
A3: Avería / producto dañado en transporte | B3: Alta | C3: 3 | E3: Manipulación en cargue / descargue | F3: Transporte | H3: Pendiente | I3: NO | K3: CG CARGA SAS | M3: BRAYAN | O3: BOGOT | Q3: 2 | R3: 5
A4: Devolución parcial | B4: Media | C4: 3 | E4: Estibado o embalaje deficiente | F4: Bodega | H4: En gestión | I4: NO | K4: GESTO AGRO S.A.S | M4: COORD. LOGÍSTICA | O4: NORTE - SUR
A5: Rechazo total del pedido | B5: Alta | C5: 2 | E5: Error de alistamiento (picking) | F5: Bodega | H5: En tránsito (retorno) | I5: NO | K5: TACMO SAS | M5: JEFE DE BODEGA | O5: CORABASTOS
A6: Faltante en la entrega | B6: Alta | C6: 2 | E6: Sobrecupo o mal acomodo en vehículo | F6: Transporte | H6: Recibida en bodega | I6: NO | K6: GOLDEN | M6: ANALISTA DE TRANSPORTE | O6: SUBA
A7: Sobrante en la entrega | B7: Baja | C7: 5 | E7: Demora del transportador | F7: Transporte | H7: En inspección | I7: NO | M7: FACTURACIÓN | O7: COTA
A8: Producto equivocado | B8: Alta | C8: 2 | E8: Falla mecánica del vehículo | F8: Transporte | H8: Escalada a transportadora | I8: NO | M8: CARTERA | O8: FUNZA
A9: Producto vencido o próximo a vencer | B9: Alta | C9: 3 | E9: Ruta mal programada | F9: Logística | H9: Pendiente nota crédito | I9: NO | M9: COMERCIAL | O9: SOACHA
A10: Empaque en mal estado | B10: Media | C10: 3 | E10: Error de digitación del pedido | F10: Comercial | H10: Resuelto / Cerrado | I10: SÍ | M10: CALIDAD | O10: GACHANCIPA
A11: Retraso en vía / entrega tardía | B11: Alta | C11: 1 | E11: Error en facturación | F11: Facturación | H11: Cerrada sin costo | I11: SÍ | O11: TOCANCIPA
A12: Cliente cerrado / no ubicado | B12: Media | C12: 2 | E12: Dirección desactualizada en maestro | F12: Comercial | H12: Anulada | I12: SÍ | O12: CHIA
A13: Cliente rechaza / no recibe | B13: Media | C13: 2 | E13: Cliente sin cupo / cartera bloqueada | F13: Cartera | O13: CAJICA
A14: Dirección errada | B14: Media | C14: 2 | E14: Cliente no disponible / fuera de horario | F14: Comercial | O14: ZIPAQUIRA
A15: Vehículo varado / falla mecánica | B15: Alta | C15: 1 | E15: Producto con baja rotación / vencido | F15: Calidad | O15: MOSQUERA
A16: Cobro pendiente / flete no liquidado | B16: Media | C16: 5 | E16: Acuerdo comercial con el cliente | F16: Comercial | O16: MADRID
A17: Cumplido / soporte no entregado | B17: Media | C17: 4 | E17: Tráfico, cierre vial u orden público | F17: Externo | O17: TENJO
A18: Diferencia en facturación o precio | B18: Media | C18: 5 | E18: Clima adverso | F18: Externo | O18: TABIO
E19: Sin causa asignada | F19: Por definir | O19: SOPO
O20: LA CALERA
O21: FACATATIVA
O22: SIBATE
O23: SABAN
